Workbook

Sheet เรียงน้ำหนัก
A1: บ้าน | B1: ไร่ | C1: น้ำหนัก | D1: จำนวนตัว | E1: น้ำหนักรวม | F1: คัง | G1: จำนวนปลากะพง | H1: นน.ปลากะพง | I1: คัง
A2: 4ก | B2: 1.25 | C2: =+เรียงบ่อ1!R33 -> #DIV/0! | D2: =+เรียงบ่อ1!R34 -> 0 | E2: =+C2*D2 -> #DIV/0! | F2: =+D2 -> 0 | G2: =+D2-F2 -> 0 | H2: =+G2*C2 -> #DIV/0!
A3: 1โก๊ะ | B3: 2 | C3: =+เรียงบ่อ1!K19 -> #DIV/0! | D3: =+เรียงบ่อ1!K20 -> 0 | E3: =+C3*D3 -> #DIV/0! | F3: 0 | G3: =+D3-F3 -> 0 | H3: =+G3*C3 -> #DIV/0!
A4: 1ก คัง | B4: 2 | C4: =+เรียงบ่อ1!R12 -> 4.6412859 | D4: =+เรียงบ่อ1!R13 -> 2345 | E4: =+C4*D4 -> 10883.815 | F4: =+D4 -> 2345 | G4: =+D4-F4 -> 0 | H4: =+G4*C4 -> 0 | I4: 1
A5: อ่าง | B5: 4 | C5: =+เรียงบ่อ1!Z12 -> 3.6891856 | D5: =+เรียงบ่อ1!Z13 -> 3975 | E5: =+C5*D5 -> 14664.513 | F5: 0 | G5: =+D5-F5 -> 3975 | H5: =+G5*C5 -> 14664.513
A6: ปลาย | B6: 2 | C6: =+เรียงบ่อ1!Z33 -> 3.2221755 | D6: =+เรียงบ่อ1!Z34 -> 2634 | E6: =+C6*D6 -> 8487.2104 | F6: 0 | G6: =+D6-F6 -> 2634 | H6: =+G6*C6 -> 8487.2104
A7: 3โก๊ะ | B7: 1.75 | C7: =+เรียงบ่อ1!G19 -> 2.8739677 | D7: =+เรียงบ่อ1!G20 -> 2503 | E7: =+C7*D7 -> 7193.5411 | F7: 0 | G7: =+D7-F7 -> 2503 | H7: =+G7*C7 -> 7193.5411
A8: 5ถนน | B8: 2.5 | C8: =+เรียงบ่อ1!R40 -> 2.861 | D8: =+เรียงบ่อ1!R41 -> 2500 | E8: =+C8*D8 -> 7152.5 | F8: 300 | G8: =+D8-F8 -> 2200 | H8: =+G8*C8 -> 6294.2
A9: 2ก คัง | B9: 2 | C9: =+เรียงบ่อ1!R19 -> 2.8068249 | D9: =+เรียงบ่อ1!R20 -> 4626 | E9: =+C9*D9 -> 12984.372 | F9: =+D9 -> 4626 | G9: =+D9-F9 -> 0 | H9: =+G9*C9 -> 0 | I9: 1
A10: อ่างโก๊ะ | B10: 2.75 | C10: =+บ่อ6โก๊ะ!P42 -> 2.6742726 | D10: =+บ่อ6โก๊ะ!T42 -> 2842 | E10: =+C10*D10 -> 7600.2827 | F10: 0 | G10: =+D10-F10 -> 2842 | H10: =+G10*C10 -> 7600.2827
A11: 1ญ | B11: 1.5 | C11: =+เรียงบ่อ1!V12 -> 2.426613 | D11: =+เรียงบ่อ1!V13 -> 2227 | E11: =+C11*D11 -> 5404.0673 | F11: 0 | G11: =+D11-F11 -> 2227 | H11: =+G11*C11 -> 5404.0673
A12: 1ฝน คัง | B12: 1.75 | C12: =+เรียงบ่อ1!N12 -> 1.8860122 | D12: =+เรียงบ่อ1!N13 -> 4372 | E12: =+C12*D12 -> 8245.6454 | F12: =+D12 -> 4372 | G12: =+D12-F12 -> 0 | H12: =+G12*C12 -> 0 | I12: 1
A13: 3ญ คัง | B13: 2.5 | C13: =+เรียงบ่อ1!V26 -> 1.7824618 | D13: =+เรียงบ่อ1!V27 -> 7361 | E13: =+C13*D13 -> 13120.701 | F13: =+D13 -> 7361 | G13: =+D13-F13 -> 0 | H13: =+G13*C13 -> 0 | I13: 1
A14: 4โก๊ะ | B14: 2.5 | C14: =+เรียงบ่อ1!E19 -> 1.6198997 | D14: =+เรียงบ่อ1!E20 -> 2300 | E14: =+C14*D14 -> 3725.7692 | F14: 0 | G14: =+D14-F14 -> 2300 | H14: =+G14*C14 -> 3725.7692
A15: 2โก๊ะ | B15: 2 | C15: =+เรียงบ่อ1!I19 -> 1.4941667 | D15: =+เรียงบ่อ1!I20 -> 2400 | E15: =+C15*D15 -> 3586 | F15: =130+300 -> 430 | G15: =+D15-F15 -> 1970 | H15: =+G15*C15 -> 2943.5083
A16: 2ญ | B16: 1.75 | C16: =+เรียงบ่อ1!V19 -> 1.3602245 | D16: =+เรียงบ่อ1!V20 -> 2494 | E16: =+C16*D16 -> 3392.4 | G16: =+D16-F16 -> 2494 | H16: =+G16*C16 -> 3392.4
A17: 3ก | B17: 1.25 | C17: =+เรียงบ่อ1!R26 -> 0.36381458 | D17: =+เรียงบ่อ1!R27 -> 6672 | E17: =+C17*D17 -> 2427.3709 | F17: 0 | G17: =+D17-F17 -> 6672 | H17: =+G17*C17 -> 2427.3709
A18: 2ฝน | B18: 1 | C18: =+เรียงบ่อ1!N19 -> 0.04 | D18: =+เรียงบ่อ1!N20 -> 6000 | E18: =+C18*D18 -> 240 | F18: 0 | G18: =+D18-F18 -> 6000 | H18: =+G18*C18 -> 240
A19: 4ญ | B19: 2.5 | C19: =+เรียงบ่อ1!V33 -> 0.025161765 | D19: =+เรียงบ่อ1!V34 -> 17000 | E19: =+C19*D19 -> 427.75 | F19: 0 | G19: =+D19-F19 -> 17000 | H19: =+G19*C19 -> 427.75
A20: 5โก๊ะ | B20: 2.25 | C20: =+เรียงบ่อ1!C19 -> 0.01124026 | D20: =+เรียงบ่อ1!C20 -> 11000 | E20: =+C20*D20 -> 123.64286 | F20: 0 | G20: =+D20-F20 -> 11000 | H20: =+G20*C20 -> 123.64286
A22: ปลาดุก | B22: 0.75

Sheet เรียงบ่อ1
P3: ข้างบ้าน | Q3: วันเลี้ยง | R3: =+#REF! -> #REF!
Q4: นน. | R4: =+#REF! -> #REF!
Q5: จำนวนตัว | R5: =+#REF! -> #REF! | T5: บ้าน
Q6: นน.รวม | R6: =+R4*R5 -> #REF!
Q7: เหยื่อ | R7: =+#REF! -> #REF!
Q8: อาหาร | R8: =+#REF! -> #REF!
Q9: ตาย | R9: =+#REF! -> #REF!
L11: 1 ฝน | M11: วันเลี้ยง | N11: =+'1ฝน'!I47 -> 1 ปี 4 เดือน 22 วัน | P11: 1 ก | Q11: วันเลี้ยง | R11: =+'1ก'!I47 -> 0 ปี 11 เดือน 27 วัน | T11: 1ญ | U11: วันเลี้ยง | V11: =+'1ญ'!#REF! -> #REF! | X11: อ่าง | Y11: วันเลี้ยง | Z11: =+อ่าง!I47 -> 0 ปี 9 เดือน 13 วัน
M12: นน. | N12: =+'1ฝน'!P42 -> 1.8860122 | Q12: นน. | R12: =+'1ก'!P42 -> 4.6412859 | U12: นน. | V12: =+'1ญ'!P42 -> 2.426613 | Y12: นน. | Z12: =+อ่าง!P42 -> 3.6891856
M13: จำนวนตัว | N13: =+'1ฝน'!T42 -> 4372 | Q13: จำนวนตัว | R13: =+'1ก'!T42 -> 2345 | U13: จำนวนตัว | V13: =+'1ญ'!T42 -> 2227 | Y13: จำนวนตัว | Z13: =+อ่าง!T42 -> 3975
M14: นน.รวม | N14: =+N12*N13 -> 8245.6454 | Q14: นน.รวม | R14: =+R12*R13 -> 10883.815 | U14: นน.รวม | V14: =+V12*V13 -> 5404.0673 | Y14: นน.รวม | Z14: =+Z12*Z13 -> 14664.513
M15: เหยื่อ | N15: =+'1ฝน'!L42 -> 32340 | Q15: เหยื่อ | R15: =+'1ก'!L42 -> 25500 | U15: เหยื่อ | V15: =+'1ญ'!L42 -> 10620 | Y15: เหยื่อ | Z15: =+อ่าง!L42 -> 48885
M16: อาหาร | N16: =+'1ฝน'!L43 -> 2393 | Q16: อาหาร | R16: =+'1ก'!L43 -> 600 | U16: อาหาร | V16: =+'1ญ'!L43 -> 2830 | Y16: อาหาร | Z16: =+อ่าง!L43 -> 4520
B17: 5 โก๊ะ | D17: 4 โก๊ะ | F17: 3 โก๊ะ | H17: 2 โก๊ะ | J17: 1 โก๊ะ | M17: ตาย | N17: =+'1ฝน'!L44 -> 835 | Q17: ตาย | R17: =+'1ก'!L44 -> -411 | U17: ตาย | V17: =+'1ญ'!L44 -> 173 | Y17: ตาย | Z17: =+อ่าง!L44 -> 25
B18: วันเลี้ยง | C18: =+'5โก๊ะ'!I47 -> 0 ปี 0 เดือน 28 วัน | D18: วันเลี้ยง | E18: =+'4โก๊ะ'!#REF! -> #REF! | F18: วันเลี้ยง | G18: =+'3โก๊ะ'!I47 -> 0 ปี 8 เดือน 25 วัน | H18: วันเลี้ยง | I18: =+'2โก๊ะ'!I47 -> 0 ปี 2 เดือน 6 วัน | J18: วันเลี้ยง | K18: =+'1โก๊ะ'!I47 -> 126 ปี 3 เดือน 2 วัน | L18: 2 ฝน | M18: วันเลี้ยง | N18: =+'2ฝน'!I47 -> #NUM! | P18: 2 ก | Q18: วันเลี้ยง | R18: =+'2ก'!I47 -> 1 ปี 2 เดือน 22 วัน | T18: 2ญ | U18: วันเลี้ยง | V18: =+'2ญ'!I47 -> 0 ปี 2 เดือน 6 วัน
B19: นน. | C19: =+'5โก๊ะ'!P42 -> 0.01124026 | D19: นน. | E19: =+'4โก๊ะ'!P42 -> 1.6198997 | F19: นน. | G19: =+'3โก๊ะ'!P42 -> 2.8739677 | H19: นน. | I19: =+'2โก๊ะ'!P42 -> 1.4941667 | J19: นน. | K19: =+'1โก๊ะ'!P42 -> #DIV/0! | M19: นน. | N19: =+'2ฝน'!P42 -> 0.04 | Q19: นน. | R19: =+'2ก'!GU34 -> 2.8068249 | U19: นน. | V19: =+'2ญ'!P42 -> 1.3602245
B20: จำนวนตัว | C20: =+'5โก๊ะ'!T42 -> 11000 | D20: จำนวนตัว | E20: =+'4โก๊ะ'!T42 -> 2300 | F20: จำนวนตัว | G20: =+'3โก๊ะ'!T42 -> 2503 | H20: จำนวนตัว | I20: =+'2โก๊ะ'!T42 -> 2400 | J20: จำนวนตัว | K20: =+'1โก๊ะ'!T42 -> 0 | M20: จำนวนตัว | N20: =+'2ฝน'!T42 -> 6000 | Q20: จำนวนตัว | R20: =+'2ก'!GV34 -> 4626 | U20: จำนวนตัว | V20: =+'2ญ'!T42 -> 2494
B21: นน.รวม | C21: =+C19*C20 -> 123.64286 | D21: นน.รวม | E21: =+E19*E20 -> 3725.7692 | F21: นน.รวม | G21: =+G19*G20 -> 7193.5411 | H21: นน.รวม | I21: =+I19*I20 -> 3586 | J21: นน.รวม | K21: =+K19*K20 -> #DIV/0! | M21: นน.รวม | N21: =+N19*N20 -> 240 | Q21: นน.รวม | R21: =+R19*R20 -> 12984.372 | U21: นน.รวม | V21: =+V19*V20 -> 3392.4
B22: เหยื่อ | C22: =+'5โก๊ะ'!L42 -> 0 | D22: เหยื่อ | E22: =+'4โก๊ะ'!L42 -> 1110 | F22: เหยื่อ | G22: =+'3โก๊ะ'!L42 -> 13230 | H22: เหยื่อ | I22: =+'2โก๊ะ'!L42 -> 0 | J22: เหยื่อ | K22: =+'1โก๊ะ'!L42 -> 0 | M22: เหยื่อ | N22: =+'[1]30.7.67 2ฝน ไสร้'!L42 -> 7200 | Q22: เหยื่อ | R22: =+'2ก'!L42 -> 31200 | U22: เหยื่อ | V22: =+'2ญ'!L42 -> 1560
B23: อาหาร | C23: =+'5โก๊ะ'!L43 -> 183 | D23: อาหาร | E23: =+'4โก๊ะ'!L43 -> 2050 | F23: อาหาร | G23: =+'3โก๊ะ'!L43 -> 4355 | H23: อาหาร | I23: =+'2โก๊ะ'!L43 -> 2660 | J23: อาหาร | K23: =+'1โก๊ะ'!L43 -> 0 | M23: อาหาร | N23: =+'[1]30.7.67 2ฝน ไสร้'!L43 -> 4326 | Q23: อาหาร | R23: =+'2ก'!L43 -> 1310 | U23: อาหาร | V23: =+'2ญ'!L43 -> 2065
B24: ตาย | C24: =+'5โก๊ะ'!L44 -> 3000 | D24: ตาย | E24: =+'4โก๊ะ'!L44 -> 0 | F24: ตาย | G24: =+'3โก๊ะ'!L44 -> 17 | H24: ตาย | I24: =+'2โก๊ะ'!L44 -> 0 | J24: ตาย | K24: =+'1โก๊ะ'!L44 -> 0 | M24: ตาย | N24: =+'[1]30.7.67 2ฝน ไสร้'!L44 -> 1461 | Q24: ตาย | R24: =+'2ก'!L44 -> -655 | U24: ตาย | V24: =+'2ญ'!L44 -> 0
P25: 3 ก | Q25: วันเลี้ยง | R25: =+'3ก'!I47 -> 0 ปี 4 เดือน 11 วัน | T25: 3ญ | U25: วันเลี้ยง | V25: =+'3ญ'!I47 -> 2 ปี 2 เดือน 16 วัน
Q26: นน. | R26: =+'3ก'!P42 -> 0.36381458 | U26: นน. | V26: =+'3ญ'!P42 -> 1.7824618
Q27: จำนวนตัว | R27: =+'3ก'!T42 -> 6672 | U27: จำนวนตัว | V27: =+'3ญ'!T42 -> 7361
Q28: นน.รวม | R28: =+R26*R27 -> 2427.3709 | U28: นน.รวม | V28: =+เรียงบ่อ1!V26*เรียงบ่อ1!V27 -> 13120.701
Q29: เหยื่อ | R29: =+'3ก'!L42 -> 0 | U29: เหยื่อ | V29: =+'3ญ'!L42 -> 71250
L30: รวม | Q30: อาหาร | R30: =+'3ก'!L43 -> 4040 | U30: อาหาร | V30: =+'3ญ'!L43 -> 6111
M31: ไซร้ ตัว | N31: =+R5+R34+V34 -> #REF! | Q31: ตาย | R31: =+'3ก'!L44 -> -70 | U31: ตาย | V31: =+'3ญ'!L44 -> 5039
M32: ไซร้ นน. | N32: =+R6+R35+V35 -> #REF! | P32: 4 ก | Q32: วันเลี้ยง | R32: =+'4ก'!I47 -> 126 ปี 3 เดือน 2 วัน | T32: 4ญ | U32: วันเลี้ยง | V32: =+'4ญ'!I47 -> 0 ปี 1 เดือน 1 วัน | X32: ปลาย | Y32: วันเลี้ยง | Z32: =+ปลาย!I47 -> 0 ปี 10 เดือน 24 วัน
Q33: นน. | R33: =+'4ก'!P42 -> #DIV/0! | U33: นน. | V33: =+'4ญ'!P42 -> 0.025161765 | Y33: นน. | Z33: =+ปลาย!P42 -> 3.2221755
M34: ยักษ์ ตัว | N34: =+C20+E20+G20+K20+I20+N13+R13+R20+R41+V13+V20+V27+Z13+Z34+V34 -> 67737 | Q34: จำนวนตัว | R34: =+'4ก'!T42 -> 0 | U34: จำนวนตัว | V34: =+'4ญ'!T42 -> 17000 | Y34: จำนวนตัว | Z34: =+ปลาย!T42 -> 2634
M35: ยักษ์ นน. | N35: =+C21+E21+G21+K21+I21+N14+R14+R21+R42+V14+V21+V28+Z14+Z35+V35 -> #DIV/0! | Q35: นน.รวม | R35: =+R33*R34 -> #DIV/0! | U35: นน.รวม | V35: =+V33*V34 -> 427.75 | Y35: นน.รวม | Z35: =+Z33*Z34 -> 8487.2104
Q36: เหยื่อ | R36: =+'4ก'!L42 -> 0 | U36: เหยื่อ | V36: =+'4ญ'!L42 -> 0 | Y36: เหยื่อ | Z36: =+ปลาย!L42 -> 23850
Q37: อาหาร | R37: =+'4ก'!L43 -> 0 | U37: อาหาร | V37: =+'4ญ'!L43 -> 753.5 | Y37: อาหาร | Z37: =+ปลาย!L43 -> 4295
Q38: ตาย | R38: =+'4ก'!L44 -> 0 | U38: ตาย | V38: =+'4ญ'!L44 -> 0 | Y38: ตาย | Z38: =+ปลาย!L44 -> 3646
P39: 5 ถนน | Q39: วันเลี้ยง | R39: =+'5ถนน'!I47 -> 0 ปี 9 เดือน 22 วัน
Q40: นน. | R40: =+'5ถนน'!P42 -> 2.861
Q41: จำนวนตัว | R41: =+'5ถนน'!T42 -> 2500
Q42: นน.รวม | R42: =+R40*R41 -> 7152.5
Q43: เหยื่อ | R43: =+'5ถนน'!L42 -> 22620
...

Sheet บ่อ (3)
A1: วันที่ | B1: 20302 | I1: 20333 | P1: 20363 | W1: 20394 | AD1: 20424 | AK1: 20455 | AR1: 20486 | AY1: 20515 | BF1: 20546 | BM1: 20576 | BT1: 20607 | CA1: 20637 | CH1: 20668 | CO1: 20699 | CV1: 20729 | DC1: 20760 | DJ1: 20790 | DQ1: 20821 | DX1: 20852 | EE1: 20880
B2: เหยื่อ | D2: อาหาร | F2: ตาย | G2: นน.ตัว | H2: จำนวนปลา | I2: เหยื่อ | K2: อาหาร | M2: ตาย | N2: นน.ตัว | O2: จำนวนปลา | P2: เหยื่อ | R2: อาหาร | T2: ตาย | U2: นน.ตัว | V2: จำนวนปลา | W2: เหยื่อ | Y2: อาหาร | AA2: ตาย | AB2: นน.ตัว | AC2: จำนวนปลา | AD2: เหยื่อ | AF2: อาหาร | AH2: ตาย | AI2: นน.ตัว | AJ2: จำนวนปลา | AK2: เหยื่อ | AM2: อาหาร | AO2: ตาย | AP2: นน.ตัว | AQ2: จำนวนปลา | AR2: เหยื่อ | AT2: อาหาร | AV2: ตาย | AW2: นน.ตัว | AX2: จำนวนปลา | AY2: เหยื่อ | BA2: อาหาร | BC2: ตาย | BD2: นน.ตัว | BE2: จำนวนปลา | BF2: เหยื่อ | BH2: อาหาร | BJ2: ตาย | BK2: นน.ตัว | BL2: จำนวนปลา | BM2: เหยื่อ | BO2: อาหาร | BQ2: ตาย | BR2: นน.ตัว | BS2: จำนวนปลา | BT2: เหยื่อ | BV2: อาหาร | BX2: ตาย | BY2: นน.ตัว | BZ2: จำนวนปลา | CA2: เหยื่อ | CC2: อาหาร | CE2: ตาย | CF2: นน.ตัว | CG2: จำนวนปลา | CH2: เหยื่อ | CJ2: อาหาร | CL2: ตาย | CM2: นน.ตัว | CN2: จำนวนปลา | CO2: เหยื่อ | CQ2: อาหาร | CS2: ตาย | CT2: นน.ตัว | CU2: จำนวนปลา | CV2: เหยื่อ | CX2: อาหาร | CZ2: ตาย | DA2: นน.ตัว | DB2: จำนวนปลา | DC2: เหยื่อ | DE2: อาหาร | DG2: ตาย | DH2: นน.ตัว | DI2: จำนวนปลา | DJ2: เหยื่อ | DL2: อาหาร | DN2: ตาย | DO2: นน.ตัว | DP2: จำนวนปลา | DQ2: เหยื่อ | DS2: อาหาร | DU2: ตาย | DV2: นน.ตัว | DW2: จำนวนปลา | DX2: เหยื่อ | DZ2: อาหาร | EB2: ตาย | EC2: นน.ตัว | ED2: จำนวนปลา | EE2: เหยื่อ | EG2: อาหาร | EI2: ตาย | EJ2: นน.ตัว | EK2: จำนวนปลา
A3: =TODAY() -> 46114 | B3: เช้า | C3: เย็น | D3: เช้า | E3: เย็น | I3: เช้า | J3: เย็น | K3: เช้า | L3: เย็น | P3: เช้า | Q3: เย็น | R3: เช้า | S3: เย็น | W3: เช้า | X3: เย็น | Y3: เช้า | Z3: เย็น | AD3: เช้า | AE3: เย็น | AF3: เช้า | AG3: เย็น | AK3: เช้า | AL3: เย็น | AM3: เช้า | AN3: เย็น | AR3: เช้า | AS3: เย็น | AT3: เช้า | AU3: เย็น | AY3: เช้า | AZ3: เย็น | BA3: เช้า | BB3: เย็น | BF3: เช้า | BG3: เย็น | BH3: เช้า | BI3: เย็น | BM3: เช้า | BN3: เย็น | BO3: เช้า | BP3: เย็น | BT3: เช้า | BU3: เย็น | BV3: เช้า | BW3: เย็น | CA3: เช้า | CB3: เย็น | CC3: เช้า | CD3: เย็น | CH3: เช้า | CI3: เย็น | CJ3: เช้า | CK3: เย็น | CO3: เช้า | CP3: เย็น | CQ3: เช้า | CR3: เย็น | CV3: เช้า | CW3: เย็น | CX3: เช้า | CY3: เย็น | DC3: เช้า | DD3: เย็น | DE3: เช้า | DF3: เย็น | DJ3: เช้า | DK3: เย็น | DL3: เช้า | DM3: เย็น | DQ3: เช้า | DR3: เย็น | DS3: เช้า | DT3: เย็น | DX3: เช้า | DY3: เย็น | DZ3: เช้า | EA3: เย็น | EE3: เช้า | EF3: เย็น | EG3: เช้า | EH3: เย็น
A4: 1 | B4: 2 | E4: 30 | G4: =((((((B4+C4)*30)/$E$50)+((D4+E4)/$E$51))+($G$35*$H$35))-(F4*$G$35))/($H$35-F4) -> 1.9568434 | H4: =$H$35-F4 -> 2235 | I4: 3 | N4: =((((((I4+J4)*30)/$E$50)+((K4+L4)/$E$51))+(G34*H34))-(F34*G34))/(O4) -> 2.2719553 | O4: =H34-M4 -> 2232 | U4: =((((((P4+Q4)*30)/$E$50)+((R4+S4)/$E$51))+(N34*O34))-(M34*N34))/(V4) -> 2.4535619 | V4: =O34-T4 -> 2228 | AB4: =((((((W4+X4)*30)/$E$50)+((Y4+Z4)/$E$51))+(U34*V34))-(T34*U34))/(AC4) -> 2.4535619 | AC4: =V34-AA4 -> 2228 | AI4: =((((((AD4+AE4)*30)/$E$50)+((AF4+AG4)/$E$51))+(AB34*AC34))-(AA34*AB34))/(AJ4) -> 2.4535619 | AJ4: =AC34-AH4 -> 2228 | AP4: =((((((AK4+AL4)*30)/$E$50)+((AM4+AN4)/$E$51))+(AI34*AJ34))-(AH34*AI34))/(AQ4) -> 2.4535619 | AQ4: =AJ34-AO4 -> 2228 | AW4: =((((((AR4+AS4)*30)/$E$50)+((AT4+AU4)/$E$51))+(AP34*AQ34))-(AO34*AP34))/(AX4) -> 2.4535619 | AX4: =AQ34-AV4 -> 2228 | BD4: =((((((AY4+AZ4)*30)/$E$50)+((BA4+BB4)/$E$51))+(AW34*AX34))-(AV34*AW34))/(BE4) -> 2.4535619 | BE4: =AX34-BC4 -> 2228 | BK4: =((((((BF4+BG4)*30)/$E$50)+((BH4+BI4)/$E$51))+(BD34*BE34))-(BC34*BD34))/(BL4) -> 2.4535619 | BL4: =BE34-BJ4 -> 2228 | BR4: =((((((BM4+BN4)*30)/$E$50)+((BO4+BP4)/$E$51))+(BK34*BL34))-(BJ34*BK34))/(BS4) -> 2.4535619 | BS4: =BL34-BQ4 -> 2228 | BY4: =((((((BT4+BU4)*30)/$E$50)+((BV4+BW4)/$E$51))+(BR34*BS34))-(BQ34*BR34))/(BZ4) -> 2.4535619 | BZ4: =BS34-BX4 -> 2228 | CF4: =((((((CA4+CB4)*30)/$E$50)+((CC4+CD4)/$E$51))+(BY34*BZ34))-(BX34*BY34))/(CG4) -> 2.4535619 | CG4: =BZ34-CE4 -> 2228 | CM4: =((((((CH4+CI4)*30)/$E$50)+((CJ4+CK4)/$E$51))+(CF34*CG34))-(CE34*CF34))/(CN4) -> 2.4535619 | CN4: =CG34-CL4 -> 2228 | CT4: =((((((CO4+CP4)*30)/$E$50)+((CQ4+CR4)/$E$51))+(CM34*CN34))-(CL34*CM34))/(CU4) -> 2.4535619 | CU4: =CN34-CS4 -> 2228 | DA4: =((((((CV4+CW4)*30)/$E$50)+((CX4+CY4)/$E$51))+(CT34*CU34))-(CS34*CT34))/(DB4) -> 2.4535619 | DB4: =CU34-CZ4 -> 2228 | DH4: =((((((DC4+DD4)*30)/$E$50)+((DE4+DF4)/$E$51))+(DA34*DB34))-(CZ34*DA34))/(DI4) -> 2.4535619 | DI4: =DB34-DG4 -> 2228 | DO4: =((((((DJ4+DK4)*30)/$E$50)+((DL4+DM4)/$E$51))+(DH34*DI34))-(DG34*DH34))/(DP4) -> 2.4535619 | DP4: =DI34-DN4 -> 2228 | DV4: =((((((DQ4+DR4)*30)/$E$50)+((DS4+DT4)/$E$51))+(DO34*DP34))-(DN34*DO34))/(DW4) -> 2.4535619 | DW4: =DP34-DU4 -> 2228 | EC4: =((((((DX4+DY4)*30)/$E$50)+((DZ4+EA4)/$E$51))+(DV34*DW34))-(DU34*DV34))/(ED4) -> 2.4535619 | ED4: =DW34-EB4 -> 2228 | EJ4: =((((((EE4+EF4)*30)/$E$50)+((EG4+EH4)/$E$51))+(EC34*ED34))-(EB34*EC34))/(EK4) -> 2.4535619 | EK4: =ED34-EI4 -> 2228
A5: 2 | B5: 3 | E5: 40 | G5: =((((((B5+C5)*30)/$E$50)+((D5+E5)/$E$51))+(G4*H4))-(F5*G4))/(H5) -> 1.9707136 | H5: =H4-F5 -> 2235 | L5: 20 | N5: =((((((I5+J5)*30)/$E$50)+((K5+L5)/$E$51))+(N4*O4))-(M5*N4))/(O5) -> 2.2755395 | O5: =O4-M5 -> 2232 | U5: =((((((P5+Q5)*30)/$E$50)+((R5+S5)/$E$51))+(U4*V4))-(T5*U4))/(V5) -> 2.4535619 | V5: =V4-T5 -> 2228 | AB5: =((((((W5+X5)*30)/$E$50)+((Y5+Z5)/$E$51))+(AB4*AC4))-(AA5*AB4))/(AC5) -> 2.4535619 | AC5: =AC4-AA5 -> 2228 | AI5: =((((((AD5+AE5)*30)/$E$50)+((AF5+AG5)/$E$51))+(AI4*AJ4))-(AH5*AI4))/(AJ5) -> 2.4535619 | AJ5: =AJ4-AH5 -> 2228 | AP5: =((((((AK5+AL5)*30)/$E$50)+((AM5+AN5)/$E$51))+(AP4*AQ4))-(AO5*AP4))/(AQ5) -> 2.4535619 | AQ5: =AQ4-AO5 -> 2228 | AW5: =((((((AR5+AS5)*30)/$E$50)+((AT5+AU5)/$E$51))+(AW4*AX4))-(AV5*AW4))/(AX5) -> 2.4535619 | AX5: =AX4-AV5 -> 2228 | BD5: =((((((AY5+AZ5)*30)/$E$50)+((BA5+BB5)/$E$51))+(BD4*BE4))-(BC5*BD4))/(BE5) -> 2.4535619 | BE5: =BE4-BC5 -> 2228 | BK5: =((((((BF5+BG5)*30)/$E$50)+((BH5+BI5)/$E$51))+(BK4*BL4))-(BJ5*BK4))/(BL5) -> 2.4535619 | BL5: =BL4-BJ5 -> 2228 | BR5: =((((((BM5+BN5)*30)/$E$50)+((BO5+BP5)/$E$51))+(BR4*BS4))-(BQ5*BR4))/(BS5) -> 2.4535619 | BS5: =BS4-BQ5 -> 2228 | BY5: =((((((BT5+BU5)*30)/$E$50)+((BV5+BW5)/$E$51))+(BY4*BZ4))-(BX5*BY4))/(BZ5) -> 2.4535619 | BZ5: =BZ4-BX5 -> 2228 | CF5: =((((((CA5+CB5)*30)/$E$50)+((CC5+CD5)/$E$51))+(CF4*CG4))-(CE5*CF4))/(CG5) -> 2.4535619 | CG5: =CG4-CE5 -> 2228 | CM5: =((((((CH5+CI5)*30)/$E$50)+((CJ5+CK5)/$E$51))+(CM4*CN4))-(CL5*CM4))/(CN5) -> 2.4535619 | CN5: =CN4-CL5 -> 2228 | CT5: =((((((CO5+CP5)*30)/$E$50)+((CQ5+CR5)/$E$51))+(CT4*CU4))-(CS5*CT4))/(CU5) -> 2.4535619 | CU5: =CU4-CS5 -> 2228 | DA5: =((((((CV5+CW5)*30)/$E$50)+((CX5+CY5)/$E$51))+(DA4*DB4))-(CZ5*DA4))/(DB5) -> 2.4535619 | DB5: =DB4-CZ5 -> 2228 | DH5: =((((((DC5+DD5)*30)/$E$50)+((DE5+DF5)/$E$51))+(DH4*DI4))-(DG5*DH4))/(DI5) -> 2.4535619 | DI5: =DI4-DG5 -> 2228 | DO5: =((((((DJ5+DK5)*30)/$E$50)+((DL5+DM5)/$E$51))+(DO4*DP4))-(DN5*DO4))/(DP5) -> 2.4535619 | DP5: =DP4-DN5 -> 2228 | DV5: =((((((DQ5+DR5)*30)/$E$50)+((DS5+DT5)/$E$51))+(DV4*DW4))-(DU5*DV4))/(DW5) -> 2.4535619 | DW5: =DW4-DU5 -> 2228 | EC5: =((((((DX5+DY5)*30)/$E$50)+((DZ5+EA5)/$E$51))+(EC4*ED4))-(EB5*EC4))/(ED5) -> 2.4535619 | ED5: =ED4-EB5 -> 2228 | EJ5: =((((((EE5+EF5)*30)/$E$50)+((EG5+EH5)/$E$51))+(EJ4*EK4))-(EI5*EJ4))/(EK5) -> 2.4535619 | EK5: =EK4-EI5 -> 2228
A6: 3 | E6: 40 | G6: =((((((B6+C6)*30)/$E$50)+((D6+E6)/$E$51))+(G5*H5))-(F6*G5))/H5 -> 1.9778725 | H6: =H5-F6 -> 2235 | I6: 3 | L6: 20 | N6: =((((((I6+J6)*30)/$E$50)+((K6+L6)/$E$51))+(N5*O5))-(M6*N5))/(O6) -> 2.2858442 | O6: =O5-M6 -> 2232 | U6: =((((((P6+Q6)*30)/$E$50)+((R6+S6)/$E$51))+(U5*V5))-(T6*U5))/(V6) -> 2.4535619 | V6: =V5-T6 -> 2228 | AB6: =((((((W6+X6)*30)/$E$50)+((Y6+Z6)/$E$51))+(AB5*AC5))-(AA6*AB5))/(AC6) -> 2.4535619 | AC6: =AC5-AA6 -> 2228 | AI6: =((((((AD6+AE6)*30)/$E$50)+((AF6+AG6)/$E$51))+(AI5*AJ5))-(AH6*AI5))/(AJ6) -> 2.4535619 | AJ6: =AJ5-AH6 -> 2228 | AP6: =((((((AK6+AL6)*30)/$E$50)+((AM6+AN6)/$E$51))+(AP5*AQ5))-(AO6*AP5))/(AQ6) -> 2.4535619 | AQ6: =AQ5-AO6 -> 2228 | AW6: =((((((AR6+AS6)*30)/$E$50)+((AT6+AU6)/$E$51))+(AW5*AX5))-(AV6*AW5))/(AX6) -> 2.4535619 | AX6: =AX5-AV6 -> 2228 | BD6: =((((((AY6+AZ6)*30)/$E$50)+((BA6+BB6)/$E$51))+(BD5*BE5))-(BC6*BD5))/(BE6) -> 2.4535619 | BE6: =BE5-BC6 -> 2228 | BK6: =((((((BF6+BG6)*30)/$E$50)+((BH6+BI6)/$E$51))+(BK5*BL5))-(BJ6*BK5))/(BL6) -> 2.4535619 | BL6: =BL5-BJ6 -> 2228 | BR6: =((((((BM6+BN6)*30)/$E$50)+((BO6+BP6)/$E$51))+(BR5*BS5))-(BQ6*BR5))/(BS6) -> 2.4535619 | BS6: =BS5-BQ6 -> 2228 | BY6: =((((((BT6+BU6)*30)/$E$50)+((BV6+BW6)/$E$51))+(BY5*BZ5))-(BX6*BY5))/(BZ6) -> 2.4535619 | BZ6: =BZ5-BX6 -> 2228 | CF6: =((((((CA6+CB6)*30)/$E$50)+((CC6+CD6)/$E$51))+(CF5*CG5))-(CE6*CF5))/(CG6) -> 2.4535619 | CG6: =CG5-CE6 -> 2228 | CM6: =((((((CH6+CI6)*30)/$E$50)+((CJ6+CK6)/$E$51))+(CM5*CN5))-(CL6*CM5))/(CN6) -> 2.4535619 | CN6: =CN5-CL6 -> 2228 | CT6: =((((((CO6+CP6)*30)/$E$50)+((CQ6+CR6)/$E$51))+(CT5*CU5))-(CS6*CT5))/(CU6) -> 2.4535619 | CU6: =CU5-CS6 -> 2228 | DA6: =((((((CV6+CW6)*30)/$E$50)+((CX6+CY6)/$E$51))+(DA5*DB5))-(CZ6*DA5))/(DB6) -> 2.4535619 | DB6: =DB5-CZ6 -> 2228 | DH6: =((((((DC6+DD6)*30)/$E$50)+((DE6+DF6)/$E$51))+(DH5*DI5))-(DG6*DH5))/(DI6) -> 2.4535619 | DI6: =DI5-DG6 -> 2228 | DO6: =((((((DJ6+DK6)*30)/$E$50)+((DL6+DM6)/$E$51))+(DO5*DP5))-(DN6*DO5))/(DP6) -> 2.4535619 | DP6: =DP5-DN6 -> 2228 | DV6: =((((((DQ6+DR6)*30)/$E$50)+((DS6+DT6)/$E$51))+(DV5*DW5))-(DU6*DV5))/(DW6) -> 2.4535619 | DW6: =DW5-DU6 -> 2228 | EC6: =((((((DX6+DY6)*30)/$E$50)+((DZ6+EA6)/$E$51))+(EC5*ED5))-(EB6*EC5))/(ED6) -> 2.4535619 | ED6: =ED5-EB6 -> 2228 | EJ6: =((((((EE6+EF6)*30)/$E$50)+((EG6+EH6)/$E$51))+(EJ5*EK5))-(EI6*EJ5))/(EK6) -> 2.4535619 | EK6: =EK5-EI6 -> 2228
A7: 4 | G7: =((((((B7+C7)*30)/$E$50)+((D7+E7)/$E$51))+(G6*H6))-(F7*G6))/(H7) -> 1.9778725 | H7: =H6-F7 -> 2235 | I7: 4 | L7: 20 | N7: =((((((I7+J7)*30)/$E$50)+((K7+L7)/$E$51))+(N6*O6))-(M7*N6))/(O7) -> 2.298389 | O7: =O6-M7 -> 2232 | U7: =((((((P7+Q7)*30)/$E$50)+((R7+S7)/$E$51))+(U6*V6))-(T7*U6))/(V7) -> 2.4535619 | V7: =V6-T7 -> 2228 | AB7: =((((((W7+X7)*30)/$E$50)+((Y7+Z7)/$E$51))+(AB6*AC6))-(AA7*AB6))/(AC7) -> 2.4535619 | AC7: =AC6-AA7 -> 2228 | AI7: =((((((AD7+AE7)*30)/$E$50)+((AF7+AG7)/$E$51))+(AI6*AJ6))-(AH7*AI6))/(AJ7) -> 2.4535619 | AJ7: =AJ6-AH7 -> 2228 | AP7: =((((((AK7+AL7)*30)/$E$50)+((AM7+AN7)/$E$51))+(AP6*AQ6))-(AO7*AP6))/(AQ7) -> 2.4535619 | AQ7: =AQ6-AO7 -> 2228 | AW7: =((((((AR7+AS7)*30)/$E$50)+((AT7+AU7)/$E$51))+(AW6*AX6))-(AV7*AW6))/(AX7) -> 2.4535619 | AX7: =AX6-AV7 -> 2228 | BD7: =((((((AY7+AZ7)*30)/$E$50)+((BA7+BB7)/$E$51))+(BD6*BE6))-(BC7*BD6))/(BE7) -> 2.4535619 | BE7: =BE6-BC7 -> 2228 | BK7: =((((((BF7+BG7)*30)/$E$50)+((BH7+BI7)/$E$51))+(BK6*BL6))-(BJ7*BK6))/(BL7) -> 2.4535619 | BL7: =BL6-BJ7 -> 2228 | BR7: =((((((BM7+BN7)*30)/$E$50)+((BO7+BP7)/$E$51))+(BR6*BS6))-(BQ7*BR6))/(BS7) -> 2.4535619 | BS7: =BS6-BQ7 -> 2228 | BY7: =((((((BT7+BU7)*30)/$E$50)+((BV7+BW7)/$E$51))+(BY6*BZ6))-(BX7*BY6))/(BZ7) -> 2.4535619 | BZ7: =BZ6-BX7 -> 2228 | CF7: =((((((CA7+CB7)*30)/$E$50)+((CC7+CD7)/$E$51))+(CF6*CG6))-(CE7*CF6))/(CG7) -> 2.4535619 | CG7: =CG6-CE7 -> 2228 | CM7: =((((((CH7+CI7)*30)/$E$50)+((CJ7+CK7)/$E$51))+(CM6*CN6))-(CL7*CM6))/(CN7) -> 2.4535619 | CN7: =CN6-CL7 -> 2228 | CT7: =((((((CO7+CP7)*30)/$E$50)+((CQ7+CR7)/$E$51))+(CT6*CU6))-(CS7*CT6))/(CU7) -> 2.4535619 | CU7: =CU6-CS7 -> 2228 | DA7: =((((((CV7+CW7)*30)/$E$50)+((CX7+CY7)/$E$51))+(DA6*DB6))-(CZ7*DA6))/(DB7) -> 2.4535619 | DB7: =DB6-CZ7 -> 2228 | DH7: =((((((DC7+DD7)*30)/$E$50)+((DE7+DF7)/$E$51))+(DH6*DI6))-(DG7*DH6))/(DI7) -> 2.4535619 | DI7: =DI6-DG7 -> 2228 | DO7: =((((((DJ7+DK7)*30)/$E$50)+((DL7+DM7)/$E$51))+(DO6*DP6))-(DN7*DO6))/(DP7) -> 2.4535619 | DP7: =DP6-DN7 -> 2228 | DV7: =((((((DQ7+DR7)*30)/$E$50)+((DS7+DT7)/$E$51))+(DV6*DW6))-(DU7*DV6))/(DW7) -> 2.4535619 | DW7: =DW6-DU7 -> 2228 | EC7: =((((((DX7+DY7)*30)/$E$50)+((DZ7+EA7)/$E$51))+(EC6*ED6))-(EB7*EC6))/(ED7) -> 2.4535619 | ED7: =ED6-EB7 -> 2228 | EJ7: =((((((EE7+EF7)*30)/$E$50)+((EG7+EH7)/$E$51))+(EJ6*EK6))-(EI7*EJ6))/(EK7) -> 2.4535619 | EK7: =EK6-EI7 -> 2228
A8: 5 | B8: 4 | E8: 40 | G8: =((((((B8+C8)*30)/$E$50)+((D8+E8)/$E$51))+(G7*H7))-(F8*G7))/(H8) -> 1.9939799 | H8: =H7-F8 -> 2235 | I8: 5 | L8: 20 | N8: =((((((I8+J8)*30)/$E$50)+((K8+L8)/$E$51))+(N7*O7))-(M8*N7))/(O8) -> 2.3131739 | O8: =O7-M8 -> 2232 | U8: =((((((P8+Q8)*30)/$E$50)+((R8+S8)/$E$51))+(U7*V7))-(T8*U7))/(V8) -> 2.4535619 | V8: =V7-T8 -> 2228 | AB8: =((((((W8+X8)*30)/$E$50)+((Y8+Z8)/$E$51))+(AB7*AC7))-(AA8*AB7))/(AC8) -> 2.4535619 | AC8: =AC7-AA8 -> 2228 | AI8: =((((((AD8+AE8)*30)/$E$50)+((AF8+AG8)/$E$51))+(AI7*AJ7))-(AH8*AI7))/(AJ8) -> 2.4535619 | AJ8: =AJ7-AH8 -> 2228 | AP8: =((((((AK8+AL8)*30)/$E$50)+((AM8+AN8)/$E$51))+(AP7*AQ7))-(AO8*AP7))/(AQ8) -> 2.4535619 | AQ8: =AQ7-AO8 -> 2228 | AW8: =((((((AR8+AS8)*30)/$E$50)+((AT8+AU8)/$E$51))+(AW7*AX7))-(AV8*AW7))/(AX8) -> 2.4535619 | AX8: =AX7-AV8 -> 2228 | BD8: =((((((AY8+AZ8)*30)/$E$50)+((BA8+BB8)/$E$51))+(BD7*BE7))-(BC8*BD7))/(BE8) -> 2.4535619 | BE8: =BE7-BC8 -> 2228 | BK8: =((((((BF8+BG8)*30)/$E$50)+((BH8+BI8)/$E$51))+(BK7*BL7))-(BJ8*BK7))/(BL8) -> 2.4535619 | BL8: =BL7-BJ8 -> 2228 | BR8: =((((((BM8+BN8)*30)/$E$50)+((BO8+BP8)/$E$51))+(BR7*BS7))-(BQ8*BR7))/(BS8) -> 2.4535619 | BS8: =BS7-BQ8 -> 2228 | BY8: =((((((BT8+BU8)*30)/$E$50)+((BV8+BW8)/$E$51))+(BY7*BZ7))-(BX8*BY7))/(BZ8) -> 2.4535619 | BZ8: =BZ7-BX8 -> 2228 | CF8: =((((((CA8+CB8)*30)/$E$50)+((CC8+CD8)/$E$51))+(CF7*CG7))-(CE8*CF7))/(CG8) -> 2.4535619 | CG8: =CG7-CE8 -> 2228 | CM8: =((((((CH8+CI8)*30)/$E$50)+((CJ8+CK8)/$E$51))+(CM7*CN7))-(CL8*CM7))/(CN8) -> 2.4535619 | CN8: =CN7-CL8 -> 2228 | CT8: =((((((CO8+CP8)*30)/$E$50)+((CQ8+CR8)/$E$51))+(CT7*CU7))-(CS8*CT7))/(CU8) -> 2.4535619 | CU8: =CU7-CS8 -> 2228 | DA8: =((((((CV8+CW8)*30)/$E$50)+((CX8+CY8)/$E$51))+(DA7*DB7))-(CZ8*DA7))/(DB8) -> 2.4535619 | DB8: =DB7-CZ8 -> 2228 | DH8: =((((((DC8+DD8)*30)/$E$50)+((DE8+DF8)/$E$51))+(DH7*DI7))-(DG8*DH7))/(DI8) -> 2.4535619 | DI8: =DI7-DG8 -> 2228 | DO8: =((((((DJ8+DK8)*30)/$E$50)+((DL8+DM8)/$E$51))+(DO7*DP7))-(DN8*DO7))/(DP8) -> 2.4535619 | DP8: =DP7-DN8 -> 2228 | DV8: =((((((DQ8+DR8)*30)/$E$50)+((DS8+DT8)/$E$51))+(DV7*DW7))-(DU8*DV7))/(DW8) -> 2.4535619 | DW8: =DW7-DU8 -> 2228 | EC8: =((((((DX8+DY8)*30)/$E$50)+((DZ8+EA8)/$E$51))+(EC7*ED7))-(EB8*EC7))/(ED8) -> 2.4535619 | ED8: =ED7-EB8 -> 2228 | EJ8: =((((((EE8+EF8)*30)/$E$50)+((EG8+EH8)/$E$51))+(EJ7*EK7))-(EI8*EJ7))/(EK8) -> 2.4535619 | EK8: =EK7-EI8 -> 2228
A9: 6 | E9: 40 | G9: =((((((B9+C9)*30)/$E$50)+((D9+E9)/$E$51))+(G8*H8))-(F9*G8))/(H9) -> 2.0011387 | H9: =H8-F9 -> 2235 | I9: 3 | N9: =((((((I9+J9)*30)/$E$50)+((K9+L9)/$E$51))+(N8*O8))-(M9*N8))/(O9) -> 2.3198944 | O9: =O8-M9 -> 2232 | U9: =((((((P9+Q9)*30)/$E$50)+((R9+S9)/$E$51))+(U8*V8))-(T9*U8))/(V9) -> 2.4535619 | V9: =V8-T9 -> 2228 | AB9: =((((((W9+X9)*30)/$E$50)+((Y9+Z9)/$E$51))+(AB8*AC8))-(AA9*AB8))/(AC9) -> 2.4535619 | AC9: =AC8-AA9 -> 2228 | AI9: =((((((AD9+AE9)*30)/$E$50)+((AF9+AG9)/$E$51))+(AI8*AJ8))-(AH9*AI8))/(AJ9) -> 2.4535619 | AJ9: =AJ8-AH9 -> 2228 | AP9: =((((((AK9+AL9)*30)/$E$50)+((AM9+AN9)/$E$51))+(AP8*AQ8))-(AO9*AP8))/(AQ9) -> 2.4535619 | AQ9: =AQ8-AO9 -> 2228 | AW9: =((((((AR9+AS9)*30)/$E$50)+((AT9+AU9)/$E$51))+(AW8*AX8))-(AV9*AW8))/(AX9) -> 2.4535619 | AX9: =AX8-AV9 -> 2228 | BD9: =((((((AY9+AZ9)*30)/$E$50)+((BA9+BB9)/$E$51))+(BD8*BE8))-(BC9*BD8))/(BE9) -> 2.4535619 | BE9: =BE8-BC9 -> 2228 | BK9: =((((((BF9+BG9)*30)/$E$50)+((BH9+BI9)/$E$51))+(BK8*BL8))-(BJ9*BK8))/(BL9) -> 2.4535619 | BL9: =BL8-BJ9 -> 2228 | BR9: =((((((BM9+BN9)*30)/$E$50)+((BO9+BP9)/$E$51))+(BR8*BS8))-(BQ9*BR8))/(BS9) -> 2.4535619 | BS9: =BS8-BQ9 -> 2228 | BY9: =((((((BT9+BU9)*30)/$E$50)+((BV9+BW9)/$E$51))+(BY8*BZ8))-(BX9*BY8))/(BZ9) -> 2.4535619 | BZ9: =BZ8-BX9 -> 2228 | CF9: =((((((CA9+CB9)*30)/$E$50)+((CC9+CD9)/$E$51))+(CF8*CG8))-(CE9*CF8))/(CG9) -> 2.4535619 | CG9: =CG8-CE9 -> 2228 | CM9: =((((((CH9+CI9)*30)/$E$50)+((CJ9+CK9)/$E$51))+(CM8*CN8))-(CL9*CM8))/(CN9) -> 2.4535619 | CN9: =CN8-CL9 -> 2228 | CT9: =((((((CO9+CP9)*30)/$E$50)+((CQ9+CR9)/$E$51))+(CT8*CU8))-(CS9*CT8))/(CU9) -> 2.4535619 | CU9: =CU8-CS9 -> 2228 | DA9: =((((((CV9+CW9)*30)/$E$50)+((CX9+CY9)/$E$51))+(DA8*DB8))-(CZ9*DA8))/(DB9) -> 2.4535619 | DB9: =DB8-CZ9 -> 2228 | DH9: =((((((DC9+DD9)*30)/$E$50)+((DE9+DF9)/$E$51))+(DH8*DI8))-(DG9*DH8))/(DI9) -> 2.4535619 | DI9: =DI8-DG9 -> 2228 | DO9: =((((((DJ9+DK9)*30)/$E$50)+((DL9+DM9)/$E$51))+(DO8*DP8))-(DN9*DO8))/(DP9) -> 2.4535619 | DP9: =DP8-DN9 -> 2228 | DV9: =((((((DQ9+DR9)*30)/$E$50)+((DS9+DT9)/$E$51))+(DV8*DW8))-(DU9*DV8))/(DW9) -> 2.4535619 | DW9: =DW8-DU9 -> 2228 | EC9: =((((((DX9+DY9)*30)/$E$50)+((DZ9+EA9)/$E$51))+(EC8*ED8))-(EB9*EC8))/(ED9) -> 2.4535619 | ED9: =ED8-EB9 -> 2228 | EJ9: =((((((EE9+EF9)*30)/$E$50)+((EG9+EH9)/$E$51))+(EJ8*EK8))-(EI9*EJ8))/(EK9) -> 2.4535619 | EK9: =EK8-EI9 -> 2228
A10: 7 | E10: 40 | G10: =((((((B10+C10)*30)/$E$50)+((D10+E10)/$E$51))+(G9*H9))-(F10*G9))/(H10) -> 2.0082975 | H10: =H9-F10 -> 2235 | I10: 3 | N10: =((((((I10+J10)*30)/$E$50)+((K10+L10)/$E$51))+(N9*O9))-(M10*N9))/(O10) -> 2.3266148 | O10: =O9-M10 -> 2232 | U10: =((((((P10+Q10)*30)/$E$50)+((R10+S10)/$E$51))+(U9*V9))-(T10*U9))/(V10) -> 2.4535619 | V10: =V9-T10 -> 2228 | AB10: =((((((W10+X10)*30)/$E$50)+((Y10+Z10)/$E$51))+(AB9*AC9))-(AA10*AB9))/(AC10) -> 2.4535619 | AC10: =AC9-AA10 -> 2228 | AI10: =((((((AD10+AE10)*30)/$E$50)+((AF10+AG10)/$E$51))+(AI9*AJ9))-(AH10*AI9))/(AJ10) -> 2.4535619 | AJ10: =AJ9-AH10 -> 2228 | AP10: =((((((AK10+AL10)*30)/$E$50)+((AM10+AN10)/$E$51))+(AP9*AQ9))-(AO10*AP9))/(AQ10) -> 2.4535619 | AQ10: =AQ9-AO10 -> 2228 | AW10: =((((((AR10+AS10)*30)/$E$50)+((AT10+AU10)/$E$51))+(AW9*AX9))-(AV10*AW9))/(AX10) -> 2.4535619 | AX10: =AX9-AV10 -> 2228 | BD10: =((((((AY10+AZ10)*30)/$E$50)+((BA10+BB10)/$E$51))+(BD9*BE9))-(BC10*BD9))/(BE10) -> 2.4535619 | BE10: =BE9-BC10 -> 2228 | BK10: =((((((BF10+BG10)*30)/$E$50)+((BH10+BI10)/$E$51))+(BK9*BL9))-(BJ10*BK9))/(BL10) -> 2.4535619 | BL10: =BL9-BJ10 -> 2228 | BR10: =((((((BM10+BN10)*30)/$E$50)+((BO10+BP10)/$E$51))+(BR9*BS9))-(BQ10*BR9))/(BS10) -> 2.4535619 | BS10: =BS9-BQ10 -> 2228 | BY10: =((((((BT10+BU10)*30)/$E$50)+((BV10+BW10)/$E$51))+(BY9*BZ9))-(BX10*BY9))/(BZ10) -> 2.4535619 | BZ10: =BZ9-BX10 -> 2228 | CF10: =((((((CA10+CB10)*30)/$E$50)+((CC10+CD10)/$E$51))+(CF9*CG9))-(CE10*CF9))/(CG10) -> 2.4535619 | CG10: =CG9-CE10 -> 2228 | CM10: =((((((CH10+CI10)*30)/$E$50)+((CJ10+CK10)/$E$51))+(CM9*CN9))-(CL10*CM9))/(CN10) -> 2.4535619 | CN10: =CN9-CL10 -> 2228 | CT10: =((((((CO10+CP10)*30)/$E$50)+((CQ10+CR10)/$E$51))+(CT9*CU9))-(CS10*CT9))/(CU10) -> 2.4535619 | CU10: =CU9-CS10 -> 2228 | DA10: =((((((CV10+CW10)*30)/$E$50)+((CX10+CY10)/$E$51))+(DA9*DB9))-(CZ10*DA9))/(DB10) -> 2.4535619 | DB10: =DB9-CZ10 -> 2228 | DH10: =((((((DC10+DD10)*30)/$E$50)+((DE10+DF10)/$E$51))+(DH9*DI9))-(DG10*DH9))/(DI10) -> 2.4535619 | DI10: =DI9-DG10 -> 2228 | DO10: =((((((DJ10+DK10)*30)/$E$50)+((DL10+DM10)/$E$51))+(DO9*DP9))-(DN10*DO9))/(DP10) -> 2.4535619 | DP10: =DP9-DN10 -> 2228 | DV10: =((((((DQ10+DR10)*30)/$E$50)+((DS10+DT10)/$E$51))+(DV9*DW9))-(DU10*DV9))/(DW10) -> 2.4535619 | DW10: =DW9-DU10 -> 2228 | EC10: =((((((DX10+DY10)*30)/$E$50)+((DZ10+EA10)/$E$51))+(EC9*ED9))-(EB10*EC9))/(ED10) -> 2.4535619 | ED10: =ED9-EB10 -> 2228 | EJ10: =((((((EE10+EF10)*30)/$E$50)+((EG10+EH10)/$E$51))+(EJ9*EK9))-(EI10*EJ9))/(EK10) -> 2.4535619 | EK10: =EK9-EI10 -> 2228
A11: 8 | B11: 4 | E11: 40 | G11: =((((((B11+C11)*30)/$E$50)+((D11+E11)/$E$51))+(G10*H10))-(F11*G10))/(H11) -> 2.0244049 | H11: =H10-F11 -> 2235 | I11: 3 | N11: =((((((I11+J11)*30)/$E$50)+((K11+L11)/$E$51))+(N10*O10))-(M11*N10))/(O11) -> 2.3333352 | O11: =O10-M11 -> 2232 | U11: =((((((P11+Q11)*30)/$E$50)+((R11+S11)/$E$51))+(U10*V10))-(T11*U10))/(V11) -> 2.4535619 | V11: =V10-T11 -> 2228 | AB11: =((((((W11+X11)*30)/$E$50)+((Y11+Z11)/$E$51))+(AB10*AC10))-(AA11*AB10))/(AC11) -> 2.4535619 | AC11: =AC10-AA11 -> 2228 | AI11: =((((((AD11+AE11)*30)/$E$50)+((AF11+AG11)/$E$51))+(AI10*AJ10))-(AH11*AI10))/(AJ11) -> 2.4535619 | AJ11: =AJ10-AH11 -> 2228 | AP11: =((((((AK11+AL11)*30)/$E$50)+((AM11+AN11)/$E$51))+(AP10*AQ10))-(AO11*AP10))/(AQ11) -> 2.4535619 | AQ11: =AQ10-AO11 -> 2228 | AW11: =((((((AR11+AS11)*30)/$E$50)+((AT11+AU11)/$E$51))+(AW10*AX10))-(AV11*AW10))/(AX11) -> 2.4535619 | AX11: =AX10-AV11 -> 2228 | BD11: =((((((AY11+AZ11)*30)/$E$50)+((BA11+BB11)/$E$51))+(BD10*BE10))-(BC11*BD10))/(BE11) -> 2.4535619 | BE11: =BE10-BC11 -> 2228 | BK11: =((((((BF11+BG11)*30)/$E$50)+((BH11+BI11)/$E$51))+(BK10*BL10))-(BJ11*BK10))/(BL11) -> 2.4535619 | BL11: =BL10-BJ11 -> 2228 | BR11: =((((((BM11+BN11)*30)/$E$50)+((BO11+BP11)/$E$51))+(BR10*BS10))-(BQ11*BR10))/(BS11) -> 2.4535619 | BS11: =BS10-BQ11 -> 2228 | BY11: =((((((BT11+BU11)*30)/$E$50)+((BV11+BW11)/$E$51))+(BY10*BZ10))-(BX11*BY10))/(BZ11) -> 2.4535619 | BZ11: =BZ10-BX11 -> 2228 | CF11: =((((((CA11+CB11)*30)/$E$50)+((CC11+CD11)/$E$51))+(CF10*CG10))-(CE11*CF10))/(CG11) -> 2.4535619 | CG11: =CG10-CE11 -> 2228 | CM11: =((((((CH11+CI11)*30)/$E$50)+((CJ11+CK11)/$E$51))+(CM10*CN10))-(CL11*CM10))/(CN11) -> 2.4535619 | CN11: =CN10-CL11 -> 2228 | CT11: =((((((CO11+CP11)*30)/$E$50)+((CQ11+CR11)/$E$51))+(CT10*CU10))-(CS11*CT10))/(CU11) -> 2.4535619 | CU11: =CU10-CS11 -> 2228 | DA11: =((((((CV11+CW11)*30)/$E$50)+((CX11+CY11)/$E$51))+(DA10*DB10))-(CZ11*DA10))/(DB11) -> 2.4535619 | DB11: =DB10-CZ11 -> 2228 | DH11: =((((((DC11+DD11)*30)/$E$50)+((DE11+DF11)/$E$51))+(DH10*DI10))-(DG11*DH10))/(DI11) -> 2.4535619 | DI11: =DI10-DG11 -> 2228 | DO11: =((((((DJ11+DK11)*30)/$E$50)+((DL11+DM11)/$E$51))+(DO10*DP10))-(DN11*DO10))/(DP11) -> 2.4535619 | DP11: =DP10-DN11 -> 2228 | DV11: =((((((DQ11+DR11)*30)/$E$50)+((DS11+DT11)/$E$51))+(DV10*DW10))-(DU11*DV10))/(DW11) -> 2.4535619 | DW11: =DW10-DU11 -> 2228 | EC11: =((((((DX11+DY11)*30)/$E$50)+((DZ11+EA11)/$E$51))+(EC10*ED10))-(EB11*EC10))/(ED11) -> 2.4535619 | ED11: =ED10-EB11 -> 2228 | EJ11: =((((((EE11+EF11)*30)/$E$50)+((EG11+EH11)/$E$51))+(EJ10*EK10))-(EI11*EJ10))/(EK11) -> 2.4535619 | EK11: =EK10-EI11 -> 2228
A12: 9 | E12: 30 | G12: =((((((B12+C12)*30)/$E$50)+((D12+E12)/$E$51))+(G11*H11))-(F12*G11))/(H12) -> 2.029774 | H12: =H11-F12 -> 2235 | I12: 3 | L12: 20 | N12: =((((((I12+J12)*30)/$E$50)+((K12+L12)/$E$51))+(N11*O11))-(M12*N11))/(O12) -> 2.3436399 | O12: =O11-M12 -> 2232 | U12: =((((((P12+Q12)*30)/$E$50)+((R12+S12)/$E$51))+(U11*V11))-(T12*U11))/(V12) -> 2.4535619 | V12: =V11-T12 -> 2228 | AB12: =((((((W12+X12)*30)/$E$50)+((Y12+Z12)/$E$51))+(AB11*AC11))-(AA12*AB11))/(AC12) -> 2.4535619 | AC12: =AC11-AA12 -> 2228 | AI12: =((((((AD12+AE12)*30)/$E$50)+((AF12+AG12)/$E$51))+(AI11*AJ11))-(AH12*AI11))/(AJ12) -> 2.4535619 | AJ12: =AJ11-AH12 -> 2228 | AP12: =((((((AK12+AL12)*30)/$E$50)+((AM12+AN12)/$E$51))+(AP11*AQ11))-(AO12*AP11))/(AQ12) -> 2.4535619 | AQ12: =AQ11-AO12 -> 2228 | AW12: =((((((AR12+AS12)*30)/$E$50)+((AT12+AU12)/$E$51))+(AW11*AX11))-(AV12*AW11))/(AX12) -> 2.4535619 | AX12: =AX11-AV12 -> 2228 | BD12: =((((((AY12+AZ12)*30)/$E$50)+((BA12+BB12)/$E$51))+(BD11*BE11))-(BC12*BD11))/(BE12) -> 2.4535619 | BE12: =BE11-BC12 -> 2228 | BK12: =((((((BF12+BG12)*30)/$E$50)+((BH12+BI12)/$E$51))+(BK11*BL11))-(BJ12*BK11))/(BL12) -> 2.4535619 | BL12: =BL11-BJ12 -> 2228 | BR12: =((((((BM12+BN12)*30)/$E$50)+((BO12+BP12)/$E$51))+(BR11*BS11))-(BQ12*BR11))/(BS12) -> 2.4535619 | BS12: =BS11-BQ12 -> 2228 | BY12: =((((((BT12+BU12)*30)/$E$50)+((BV12+BW12)/$E$51))+(BY11*BZ11))-(BX12*BY11))/(BZ12) -> 2.4535619 | BZ12: =BZ11-BX12 -> 2228 | CF12: =((((((CA12+CB12)*30)/$E$50)+((CC12+CD12)/$E$51))+(CF11*CG11))-(CE12*CF11))/(CG12) -> 2.4535619 | CG12: =CG11-CE12 -> 2228 | CM12: =((((((CH12+CI12)*30)/$E$50)+((CJ12+CK12)/$E$51))+(CM11*CN11))-(CL12*CM11))/(CN12) -> 2.4535619 | CN12: =CN11-CL12 -> 2228 | CT12: =((((((CO12+CP12)*30)/$E$50)+((CQ12+CR12)/$E$51))+(CT11*CU11))-(CS12*CT11))/(CU12) -> 2.4535619 | CU12: =CU11-CS12 -> 2228 | DA12: =((((((CV12+CW12)*30)/$E$50)+((CX12+CY12)/$E$51))+(DA11*DB11))-(CZ12*DA11))/(DB12) -> 2.4535619 | DB12: =DB11-CZ12 -> 2228 | DH12: =((((((DC12+DD12)*30)/$E$50)+((DE12+DF12)/$E$51))+(DH11*DI11))-(DG12*DH11))/(DI12) -> 2.4535619 | DI12: =DI11-DG12 -> 2228 | DO12: =((((((DJ12+DK12)*30)/$E$50)+((DL12+DM12)/$E$51))+(DO11*DP11))-(DN12*DO11))/(DP12) -> 2.4535619 | DP12: =DP11-DN12 -> 2228 | DV12: =((((((DQ12+DR12)*30)/$E$50)+((DS12+DT12)/$E$51))+(DV11*DW11))-(DU12*DV11))/(DW12) -> 2.4535619 | DW12: =DW11-DU12 -> 2228 | EC12: =((((((DX12+DY12)*30)/$E$50)+((DZ12+EA12)/$E$51))+(EC11*ED11))-(EB12*EC11))/(ED12) -> 2.4535619 | ED12: =ED11-EB12 -> 2228 | EJ12: =((((((EE12+EF12)*30)/$E$50)+((EG12+EH12)/$E$51))+(EJ11*EK11))-(EI12*EJ11))/(EK12) -> 2.4535619 | EK12: =EK11-EI12 -> 2228
A13: 10 | B13: 3 | E13: 20 | G13: =((((((B13+C13)*30)/$E$50)+((D13+E13)/$E$51))+(G12*H12))-(F13*G12))/(H13) -> 2.0400649 | H13: =H12-F13 -> 2235 | I13: 5 | L13: 20 | N13: =((((((I13+J13)*30)/$E$50)+((K13+L13)/$E$51))+(N12*O12))-(M13*N12))/(O13) -> 2.3584248 | O13: =O12-M13 -> 2232 | U13: =((((((P13+Q13)*30)/$E$50)+((R13+S13)/$E$51))+(U12*V12))-(T13*U12))/(V13) -> 2.4535619 | V13: =V12-T13 -> 2228 | AB13: =((((((W13+X13)*30)/$E$50)+((Y13+Z13)/$E$51))+(AB12*AC12))-(AA13*AB12))/(AC13) -> 2.4535619 | AC13: =AC12-AA13 -> 2228 | AI13: =((((((AD13+AE13)*30)/$E$50)+((AF13+AG13)/$E$51))+(AI12*AJ12))-(AH13*AI12))/(AJ13) -> 2.4535619 | AJ13: =AJ12-AH13 -> 2228 | AP13: =((((((AK13+AL13)*30)/$E$50)+((AM13+AN13)/$E$51))+(AP12*AQ12))-(AO13*AP12))/(AQ13) -> 2.4535619 | AQ13: =AQ12-AO13 -> 2228 | AW13: =((((((AR13+AS13)*30)/$E$50)+((AT13+AU13)/$E$51))+(AW12*AX12))-(AV13*AW12))/(AX13) -> 2.4535619 | AX13: =AX12-AV13 -> 2228 | BD13: =((((((AY13+AZ13)*30)/$E$50)+((BA13+BB13)/$E$51))+(BD12*BE12))-(BC13*BD12))/(BE13) -> 2.4535619 | BE13: =BE12-BC13 -> 2228 | BK13: =((((((BF13+BG13)*30)/$E$50)+((BH13+BI13)/$E$51))+(BK12*BL12))-(BJ13*BK12))/(BL13) -> 2.4535619 | BL13: =BL12-BJ13 -> 2228 | BR13: =((((((BM13+BN13)*30)/$E$50)+((BO13+BP13)/$E$51))+(BR12*BS12))-(BQ13*BR12))/(BS13) -> 2.4535619 | BS13: =BS12-BQ13 -> 2228 | BY13: =((((((BT13+BU13)*30)/$E$50)+((BV13+BW13)/$E$51))+(BY12*BZ12))-(BX13*BY12))/(BZ13) -> 2.4535619 | BZ13: =BZ12-BX13 -> 2228 | CF13: =((((((CA13+CB13)*30)/$E$50)+((CC13+CD13)/$E$51))+(CF12*CG12))-(CE13*CF12))/(CG13) -> 2.4535619 | CG13: =CG12-CE13 -> 2228 | CM13: =((((((CH13+CI13)*30)/$E$50)+((CJ13+CK13)/$E$51))+(CM12*CN12))-(CL13*CM12))/(CN13) -> 2.4535619 | CN13: =CN12-CL13 -> 2228 | CT13: =((((((CO13+CP13)*30)/$E$50)+((CQ13+CR13)/$E$51))+(CT12*CU12))-(CS13*CT12))/(CU13) -> 2.4535619 | CU13: =CU12-CS13 -> 2228 | DA13: =((((((CV13+CW13)*30)/$E$50)+((CX13+CY13)/$E$51))+(DA12*DB12))-(CZ13*DA12))/(DB13) -> 2.4535619 | DB13: =DB12-CZ13 -> 2228 | DH13: =((((((DC13+DD13)*30)/$E$50)+((DE13+DF13)/$E$51))+(DH12*DI12))-(DG13*DH12))/(DI13) -> 2.4535619 | DI13: =DI12-DG13 -> 2228 | DO13: =((((((DJ13+DK13)*30)/$E$50)+((DL13+DM13)/$E$51))+(DO12*DP12))-(DN13*DO12))/(DP13) -> 2.4535619 | DP13: =DP12-DN13 -> 2228 | DV13: =((((((DQ13+DR13)*30)/$E$50)+((DS13+DT13)/$E$51))+(DV12*DW12))-(DU13*DV12))/(DW13) -> 2.4535619 | DW13: =DW12-DU13 -> 2228 | EC13: =((((((DX13+DY13)*30)/$E$50)+((DZ13+EA13)/$E$51))+(EC12*ED12))-(EB13*EC12))/(ED13) -> 2.4535619 | ED13: =ED12-EB13 -> 2228 | EJ13: =((((((EE13+EF13)*30)/$E$50)+((EG13+EH13)/$E$51))+(EJ12*EK12))-(EI13*EJ12))/(EK13) -> 2.4535619 | EK13: =EK12-EI13 -> 2228
A14: 11 | D14: 20 | G14: =((((((B14+C14)*30)/$E$50)+((D14+E14)/$E$51))+(G13*H13))-(F14*G13))/(H14) -> 2.0436443 | H14: =H13-F14 -> 2235 | I14: 3 | L14: 30 | M14: 2 | N14: =((((((I14+J14)*30)/$E$50)+((K14+L14)/$E$51))+(N13*O13))-(M14*N13))/(O14) -> 2.3705324 | O14: =O13-M14 -> 2230 | U14: =((((((P14+Q14)*30)/$E$50)+((R14+S14)/$E$51))+(U13*V13))-(T14*U13))/(V14) -> 2.4535619 | V14: =V13-T14 -> 2228 | AB14: =((((((W14+X14)*30)/$E$50)+((Y14+Z14)/$E$51))+(AB13*AC13))-(AA14*AB13))/(AC14) -> 2.4535619 | AC14: =AC13-AA14 -> 2228 | AI14: =((((((AD14+AE14)*30)/$E$50)+((AF14+AG14)/$E$51))+(AI13*AJ13))-(AH14*AI13))/(AJ14) -> 2.4535619 | AJ14: =AJ13-AH14 -> 2228 | AP14: =((((((AK14+AL14)*30)/$E$50)+((AM14+AN14)/$E$51))+(AP13*AQ13))-(AO14*AP13))/(AQ14) -> 2.4535619 | AQ14: =AQ13-AO14 -> 2228 | AW14: =((((((AR14+AS14)*30)/$E$50)+((AT14+AU14)/$E$51))+(AW13*AX13))-(AV14*AW13))/(AX14) -> 2.4535619 | AX14: =AX13-AV14 -> 2228 | BD14: =((((((AY14+AZ14)*30)/$E$50)+((BA14+BB14)/$E$51))+(BD13*BE13))-(BC14*BD13))/(BE14) -> 2.4535619 | BE14: =BE13-BC14 -> 2228 | BK14: =((((((BF14+BG14)*30)/$E$50)+((BH14+BI14)/$E$51))+(BK13*BL13))-(BJ14*BK13))/(BL14) -> 2.4535619 | BL14: =BL13-BJ14 -> 2228 | BR14: =((((((BM14+BN14)*30)/$E$50)+((BO14+BP14)/$E$51))+(BR13*BS13))-(BQ14*BR13))/(BS14) -> 2.4535619 | BS14: =BS13-BQ14 -> 2228 | BY14: =((((((BT14+BU14)*30)/$E$50)+((BV14+BW14)/$E$51))+(BY13*BZ13))-(BX14*BY13))/(BZ14) -> 2.4535619 | BZ14: =BZ13-BX14 -> 2228 | CF14: =((((((CA14+CB14)*30)/$E$50)+((CC14+CD14)/$E$51))+(CF13*CG13))-(CE14*CF13))/(CG14) -> 2.4535619 | CG14: =CG13-CE14 -> 2228 | CM14: =((((((CH14+CI14)*30)/$E$50)+((CJ14+CK14)/$E$51))+(CM13*CN13))-(CL14*CM13))/(CN14) -> 2.4535619 | CN14: =CN13-CL14 -> 2228 | CT14: =((((((CO14+CP14)*30)/$E$50)+((CQ14+CR14)/$E$51))+(CT13*CU13))-(CS14*CT13))/(CU14) -> 2.4535619 | CU14: =CU13-CS14 -> 2228 | DA14: =((((((CV14+CW14)*30)/$E$50)+((CX14+CY14)/$E$51))+(DA13*DB13))-(CZ14*DA13))/(DB14) -> 2.4535619 | DB14: =DB13-CZ14 -> 2228 | DH14: =((((((DC14+DD14)*30)/$E$50)+((DE14+DF14)/$E$51))+(DH13*DI13))-(DG14*DH13))/(DI14) -> 2.4535619 | DI14: =DI13-DG14 -> 2228 | DO14: =((((((DJ14+DK14)*30)/$E$50)+((DL14+DM14)/$E$51))+(DO13*DP13))-(DN14*DO13))/(DP14) -> 2.4535619 | DP14: =DP13-DN14 -> 2228 | DV14: =((((((DQ14+DR14)*30)/$E$50)+((DS14+DT14)/$E$51))+(DV13*DW13))-(DU14*DV13))/(DW14) -> 2.4535619 | DW14: =DW13-DU14 -> 2228 | EC14: =((((((DX14+DY14)*30)/$E$50)+((DZ14+EA14)/$E$51))+(EC13*ED13))-(EB14*EC13))/(ED14) -> 2.4535619 | ED14: =ED13-EB14 -> 2228 | EJ14: =((((((EE14+EF14)*30)/$E$50)+((EG14+EH14)/$E$51))+(EJ13*EK13))-(EI14*EJ13))/(EK14) -> 2.4535619 | EK14: =EK13-EI14 -> 2228
A15: 12 | B15: 4 | E15: 40 | G15: =((((((B15+C15)*30)/$E$50)+((D15+E15)/$E$51))+(G14*H14))-(F15*G14))/(H15) -> 2.0597517 | H15: =H14-F15 -> 2235 | I15: 3 | L15: 20 | M15: 1 | N15: =((((((I15+J15)*30)/$E$50)+((K15+L15)/$E$51))+(N14*O14))-(M15*N14))/(O15) -> 2.380851 | O15: =O14-M15 -> 2229 | U15: =((((((P15+Q15)*30)/$E$50)+((R15+S15)/$E$51))+(U14*V14))-(T15*U14))/(V15) -> 2.4535619 | V15: =V14-T15 -> 2228 | AB15: =((((((W15+X15)*30)/$E$50)+((Y15+Z15)/$E$51))+(AB14*AC14))-(AA15*AB14))/(AC15) -> 2.4535619 | AC15: =AC14-AA15 -> 2228 | AI15: =((((((AD15+AE15)*30)/$E$50)+((AF15+AG15)/$E$51))+(AI14*AJ14))-(AH15*AI14))/(AJ15) -> 2.4535619 | AJ15: =AJ14-AH15 -> 2228 | AP15: =((((((AK15+AL15)*30)/$E$50)+((AM15+AN15)/$E$51))+(AP14*AQ14))-(AO15*AP14))/(AQ15) -> 2.4535619 | AQ15: =AQ14-AO15 -> 2228 | AW15: =((((((AR15+AS15)*30)/$E$50)+((AT15+AU15)/$E$51))+(AW14*AX14))-(AV15*AW14))/(AX15) -> 2.4535619 | AX15: =AX14-AV15 -> 2228 | BD15: =((((((AY15+AZ15)*30)/$E$50)+((BA15+BB15)/$E$51))+(BD14*BE14))-(BC15*BD14))/(BE15) -> 2.4535619 | BE15: =BE14-BC15 -> 2228 | BK15: =((((((BF15+BG15)*30)/$E$50)+((BH15+BI15)/$E$51))+(BK14*BL14))-(BJ15*BK14))/(BL15) -> 2.4535619 | BL15: =BL14-BJ15 -> 2228 | BR15: =((((((BM15+BN15)*30)/$E$50)+((BO15+BP15)/$E$51))+(BR14*BS14))-(BQ15*BR14))/(BS15) -> 2.4535619 | BS15: =BS14-BQ15 -> 2228 | BY15: =((((((BT15+BU15)*30)/$E$50)+((BV15+BW15)/$E$51))+(BY14*BZ14))-(BX15*BY14))/(BZ15) -> 2.4535619 | BZ15: =BZ14-BX15 -> 2228 | CF15: =((((((CA15+CB15)*30)/$E$50)+((CC15+CD15)/$E$51))+(CF14*CG14))-(CE15*CF14))/(CG15) -> 2.4535619 | CG15: =CG14-CE15 -> 2228 | CM15: =((((((CH15+CI15)*30)/$E$50)+((CJ15+CK15)/$E$51))+(CM14*CN14))-(CL15*CM14))/(CN15) -> 2.4535619 | CN15: =CN14-CL15 -> 2228 | CT15: =((((((CO15+CP15)*30)/$E$50)+((CQ15+CR15)/$E$51))+(CT14*CU14))-(CS15*CT14))/(CU15) -> 2.4535619 | CU15: =CU14-CS15 -> 2228 | DA15: =((((((CV15+CW15)*30)/$E$50)+((CX15+CY15)/$E$51))+(DA14*DB14))-(CZ15*DA14))/(DB15) -> 2.4535619 | DB15: =DB14-CZ15 -> 2228 | DH15: =((((((DC15+DD15)*30)/$E$50)+((DE15+DF15)/$E$51))+(DH14*DI14))-(DG15*DH14))/(DI15) -> 2.4535619 | DI15: =DI14-DG15 -> 2228 | DO15: =((((((DJ15+DK15)*30)/$E$50)+((DL15+DM15)/$E$51))+(DO14*DP14))-(DN15*DO14))/(DP15) -> 2.4535619 | DP15: =DP14-DN15 -> 2228 | DV15: =((((((DQ15+DR15)*30)/$E$50)+((DS15+DT15)/$E$51))+(DV14*DW14))-(DU15*DV14))/(DW15) -> 2.4535619 | DW15: =DW14-DU15 -> 2228 | EC15: =((((((DX15+DY15)*30)/$E$50)+((DZ15+EA15)/$E$51))+(EC14*ED14))-(EB15*EC14))/(ED15) -> 2.4535619 | ED15: =ED14-EB15 -> 2228 | EJ15: =((((((EE15+EF15)*30)/$E$50)+((EG15+EH15)/$E$51))+(EJ14*EK14))-(EI15*EJ14))/(EK15) -> 2.4535619 | EK15: =EK14-EI15 -> 2228
A16: 13 | B16: 5 | G16: =((((((B16+C16)*30)/$E$50)+((D16+E16)/$E$51))+(G15*H15))-(F16*G15))/(H16) -> 2.0709374 | H16: =H15-F16 -> 2235 | I16: 6 | L16: 20 | M16: 1 | N16: =((((((I16+J16)*30)/$E$50)+((K16+L16)/$E$51))+(N15*O15))-(M16*N15))/(O16) -> 2.3979066 | O16: =O15-M16 -> 2228 | U16: =((((((P16+Q16)*30)/$E$50)+((R16+S16)/$E$51))+(U15*V15))-(T16*U15))/(V16) -> 2.4535619 | V16: =V15-T16 -> 2228 | AB16: =((((((W16+X16)*30)/$E$50)+((Y16+Z16)/$E$51))+(AB15*AC15))-(AA16*AB15))/(AC16) -> 2.4535619 | AC16: =AC15-AA16 -> 2228 | AI16: =((((((AD16+AE16)*30)/$E$50)+((AF16+AG16)/$E$51))+(AI15*AJ15))-(AH16*AI15))/(AJ16) -> 2.4535619 | AJ16: =AJ15-AH16 -> 2228 | AP16: =((((((AK16+AL16)*30)/$E$50)+((AM16+AN16)/$E$51))+(AP15*AQ15))-(AO16*AP15))/(AQ16) -> 2.4535619 | AQ16: =AQ15-AO16 -> 2228 | AW16: =((((((AR16+AS16)*30)/$E$50)+((AT16+AU16)/$E$51))+(AW15*AX15))-(AV16*AW15))/(AX16) -> 2.4535619 | AX16: =AX15-AV16 -> 2228 | BD16: =((((((AY16+AZ16)*30)/$E$50)+((BA16+BB16)/$E$51))+(BD15*BE15))-(BC16*BD15))/(BE16) -> 2.4535619 | BE16: =BE15-BC16 -> 2228 | BK16: =((((((BF16+BG16)*30)/$E$50)+((BH16+BI16)/$E$51))+(BK15*BL15))-(BJ16*BK15))/(BL16) -> 2.4535619 | BL16: =BL15-BJ16 -> 2228 | BR16: =((((((BM16+BN16)*30)/$E$50)+((BO16+BP16)/$E$51))+(BR15*BS15))-(BQ16*BR15))/(BS16) -> 2.4535619 | BS16: =BS15-BQ16 -> 2228 | BY16: =((((((BT16+BU16)*30)/$E$50)+((BV16+BW16)/$E$51))+(BY15*BZ15))-(BX16*BY15))/(BZ16) -> 2.4535619 | BZ16: =BZ15-BX16 -> 2228 | CF16: =((((((CA16+CB16)*30)/$E$50)+((CC16+CD16)/$E$51))+(CF15*CG15))-(CE16*CF15))/(CG16) -> 2.4535619 | CG16: =CG15-CE16 -> 2228 | CM16: =((((((CH16+CI16)*30)/$E$50)+((CJ16+CK16)/$E$51))+(CM15*CN15))-(CL16*CM15))/(CN16) -> 2.4535619 | CN16: =CN15-CL16 -> 2228 | CT16: =((((((CO16+CP16)*30)/$E$50)+((CQ16+CR16)/$E$51))+(CT15*CU15))-(CS16*CT15))/(CU16) -> 2.4535619 | CU16: =CU15-CS16 -> 2228 | DA16: =((((((CV16+CW16)*30)/$E$50)+((CX16+CY16)/$E$51))+(DA15*DB15))-(CZ16*DA15))/(DB16) -> 2.4535619 | DB16: =DB15-CZ16 -> 2228 | DH16: =((((((DC16+DD16)*30)/$E$50)+((DE16+DF16)/$E$51))+(DH15*DI15))-(DG16*DH15))/(DI16) -> 2.4535619 | DI16: =DI15-DG16 -> 2228 | DO16: =((((((DJ16+DK16)*30)/$E$50)+((DL16+DM16)/$E$51))+(DO15*DP15))-(DN16*DO15))/(DP16) -> 2.4535619 | DP16: =DP15-DN16 -> 2228 | DV16: =((((((DQ16+DR16)*30)/$E$50)+((DS16+DT16)/$E$51))+(DV15*DW15))-(DU16*DV15))/(DW16) -> 2.4535619 | DW16: =DW15-DU16 -> 2228 | EC16: =((((((DX16+DY16)*30)/$E$50)+((DZ16+EA16)/$E$51))+(EC15*ED15))-(EB16*EC15))/(ED16) -> 2.4535619 | ED16: =ED15-EB16 -> 2228 | EJ16: =((((((EE16+EF16)*30)/$E$50)+((EG16+EH16)/$E$51))+(EJ15*EK15))-(EI16*EJ15))/(EK16) -> 2.4535619 | EK16: =EK15-EI16 -> 2228
A17: 14 | B17: 5 | E17: 40 | G17: =((((((B17+C17)*30)/$E$50)+((D17+E17)/$E$51))+(G16*H16))-(F17*G16))/(H17) -> 2.0892819 | H17: =H16-F17 -> 2235 | I17: 3 | L17: 20 | N17: =((((((I17+J17)*30)/$E$50)+((K17+L17)/$E$51))+(N16*O16))-(M17*N16))/(O17) -> 2.4082298 | O17: =O16-M17 -> 2228 | U17: =((((((P17+Q17)*30)/$E$50)+((R17+S17)/$E$51))+(U16*V16))-(T17*U16))/(V17) -> 2.4535619 | V17: =V16-T17 -> 2228 | AB17: =((((((W17+X17)*30)/$E$50)+((Y17+Z17)/$E$51))+(AB16*AC16))-(AA17*AB16))/(AC17) -> 2.4535619 | AC17: =AC16-AA17 -> 2228 | AI17: =((((((AD17+AE17)*30)/$E$50)+((AF17+AG17)/$E$51))+(AI16*AJ16))-(AH17*AI16))/(AJ17) -> 2.4535619 | AJ17: =AJ16-AH17 -> 2228 | AP17: =((((((AK17+AL17)*30)/$E$50)+((AM17+AN17)/$E$51))+(AP16*AQ16))-(AO17*AP16))/(AQ17) -> 2.4535619 | AQ17: =AQ16-AO17 -> 2228 | AW17: =((((((AR17+AS17)*30)/$E$50)+((AT17+AU17)/$E$51))+(AW16*AX16))-(AV17*AW16))/(AX17) -> 2.4535619 | AX17: =AX16-AV17 -> 2228 | BD17: =((((((AY17+AZ17)*30)/$E$50)+((BA17+BB17)/$E$51))+(BD16*BE16))-(BC17*BD16))/(BE17) -> 2.4535619 | BE17: =BE16-BC17 -> 2228 | BK17: =((((((BF17+BG17)*30)/$E$50)+((BH17+BI17)/$E$51))+(BK16*BL16))-(BJ17*BK16))/(BL17) -> 2.4535619 | BL17: =BL16-BJ17 -> 2228 | BR17: =((((((BM17+BN17)*30)/$E$50)+((BO17+BP17)/$E$51))+(BR16*BS16))-(BQ17*BR16))/(BS17) -> 2.4535619 | BS17: =BS16-BQ17 -> 2228 | BY17: =((((((BT17+BU17)*30)/$E$50)+((BV17+BW17)/$E$51))+(BY16*BZ16))-(BX17*BY16))/(BZ17) -> 2.4535619 | BZ17: =BZ16-BX17 -> 2228 | CF17: =((((((CA17+CB17)*30)/$E$50)+((CC17+CD17)/$E$51))+(CF16*CG16))-(CE17*CF16))/(CG17) -> 2.4535619 | CG17: =CG16-CE17 -> 2228 | CM17: =((((((CH17+CI17)*30)/$E$50)+((CJ17+CK17)/$E$51))+(CM16*CN16))-(CL17*CM16))/(CN17) -> 2.4535619 | CN17: =CN16-CL17 -> 2228 | CT17: =((((((CO17+CP17)*30)/$E$50)+((CQ17+CR17)/$E$51))+(CT16*CU16))-(CS17*CT16))/(CU17) -> 2.4535619 | CU17: =CU16-CS17 -> 2228 | DA17: =((((((CV17+CW17)*30)/$E$50)+((CX17+CY17)/$E$51))+(DA16*DB16))-(CZ17*DA16))/(DB17) -> 2.4535619 | DB17: =DB16-CZ17 -> 2228 | DH17: =((((((DC17+DD17)*30)/$E$50)+((DE17+DF17)/$E$51))+(DH16*DI16))-(DG17*DH16))/(DI17) -> 2.4535619 | DI17: =DI16-DG17 -> 2228 | DO17: =((((((DJ17+DK17)*30)/$E$50)+((DL17+DM17)/$E$51))+(DO16*DP16))-(DN17*DO16))/(DP17) -> 2.4535619 | DP17: =DP16-DN17 -> 2228 | DV17: =((((((DQ17+DR17)*30)/$E$50)+((DS17+DT17)/$E$51))+(DV16*DW16))-(DU17*DV16))/(DW17) -> 2.4535619 | DW17: =DW16-DU17 -> 2228 | EC17: =((((((DX17+DY17)*30)/$E$50)+((DZ17+EA17)/$E$51))+(EC16*ED16))-(EB17*EC16))/(ED17) -> 2.4535619 | ED17: =ED16-EB17 -> 2228 | EJ17: =((((((EE17+EF17)*30)/$E$50)+((EG17+EH17)/$E$51))+(EJ16*EK16))-(EI17*EJ16))/(EK17) -> 2.4535619 | EK17: =EK16-EI17 -> 2228
A18: 15 | B18: 5 | E18: 40 | G18: =((((((B18+C18)*30)/$E$50)+((D18+E18)/$E$51))+(G17*H17))-(F18*G17))/(H18) -> 2.1076264 | H18: =H17-F18 -> 2235 | I18: 5 | N18: =((((((I18+J18)*30)/$E$50)+((K18+L18)/$E$51))+(N17*O17))-(M18*N17))/(O18) -> 2.4194506 | O18: =O17-M18 -> 2228 | U18: =((((((P18+Q18)*30)/$E$50)+((R18+S18)/$E$51))+(U17*V17))-(T18*U17))/(V18) -> 2.4535619 | V18: =V17-T18 -> 2228 | AB18: =((((((W18+X18)*30)/$E$50)+((Y18+Z18)/$E$51))+(AB17*AC17))-(AA18*AB17))/(AC18) -> 2.4535619 | AC18: =AC17-AA18 -> 2228 | AI18: =((((((AD18+AE18)*30)/$E$50)+((AF18+AG18)/$E$51))+(AI17*AJ17))-(AH18*AI17))/(AJ18) -> 2.4535619 | AJ18: =AJ17-AH18 -> 2228 | AP18: =((((((AK18+AL18)*30)/$E$50)+((AM18+AN18)/$E$51))+(AP17*AQ17))-(AO18*AP17))/(AQ18) -> 2.4535619 | AQ18: =AQ17-AO18 -> 2228 | AW18: =((((((AR18+AS18)*30)/$E$50)+((AT18+AU18)/$E$51))+(AW17*AX17))-(AV18*AW17))/(AX18) -> 2.4535619 | AX18: =AX17-AV18 -> 2228 | BD18: =((((((AY18+AZ18)*30)/$E$50)+((BA18+BB18)/$E$51))+(BD17*BE17))-(BC18*BD17))/(BE18) -> 2.4535619 | BE18: =BE17-BC18 -> 2228 | BK18: =((((((BF18+BG18)*30)/$E$50)+((BH18+BI18)/$E$51))+(BK17*BL17))-(BJ18*BK17))/(BL18) -> 2.4535619 | BL18: =BL17-BJ18 -> 2228 | BR18: =((((((BM18+BN18)*30)/$E$50)+((BO18+BP18)/$E$51))+(BR17*BS17))-(BQ18*BR17))/(BS18) -> 2.4535619 | BS18: =BS17-BQ18 -> 2228 | BY18: =((((((BT18+BU18)*30)/$E$50)+((BV18+BW18)/$E$51))+(BY17*BZ17))-(BX18*BY17))/(BZ18) -> 2.4535619 | BZ18: =BZ17-BX18 -> 2228 | CF18: =((((((CA18+CB18)*30)/$E$50)+((CC18+CD18)/$E$51))+(CF17*CG17))-(CE18*CF17))/(CG18) -> 2.4535619 | CG18: =CG17-CE18 -> 2228 | CM18: =((((((CH18+CI18)*30)/$E$50)+((CJ18+CK18)/$E$51))+(CM17*CN17))-(CL18*CM17))/(CN18) -> 2.4535619 | CN18: =CN17-CL18 -> 2228 | CT18: =((((((CO18+CP18)*30)/$E$50)+((CQ18+CR18)/$E$51))+(CT17*CU17))-(CS18*CT17))/(CU18) -> 2.4535619 | CU18: =CU17-CS18 -> 2228 | DA18: =((((((CV18+CW18)*30)/$E$50)+((CX18+CY18)/$E$51))+(DA17*DB17))-(CZ18*DA17))/(DB18) -> 2.4535619 | DB18: =DB17-CZ18 -> 2228 | DH18: =((((((DC18+DD18)*30)/$E$50)+((DE18+DF18)/$E$51))+(DH17*DI17))-(DG18*DH17))/(DI18) -> 2.4535619 | DI18: =DI17-DG18 -> 2228 | DO18: =((((((DJ18+DK18)*30)/$E$50)+((DL18+DM18)/$E$51))+(DO17*DP17))-(DN18*DO17))/(DP18) -> 2.4535619 | DP18: =DP17-DN18 -> 2228 | DV18: =((((((DQ18+DR18)*30)/$E$50)+((DS18+DT18)/$E$51))+(DV17*DW17))-(DU18*DV17))/(DW18) -> 2.4535619 | DW18: =DW17-DU18 -> 2228 | EC18: =((((((DX18+DY18)*30)/$E$50)+((DZ18+EA18)/$E$51))+(EC17*ED17))-(EB18*EC17))/(ED18) -> 2.4535619 | ED18: =ED17-EB18 -> 2228 | EJ18: =((((((EE18+EF18)*30)/$E$50)+((EG18+EH18)/$E$51))+(EJ17*EK17))-(EI18*EJ17))/(EK18) -> 2.4535619 | EK18: =EK17-EI18 -> 2228
A19: 16 | B19: 4 | E19: 20 | G19: =((((((B19+C19)*30)/$E$50)+((D19+E19)/$E$51))+(G18*H18))-(F19*G18))/(H19) -> 2.1201544 | H19: =H18-F19 -> 2235 | I19: 3 | L19: 20 | N19: =((((((I19+J19)*30)/$E$50)+((K19+L19)/$E$51))+(N18*O18))-(M19*N18))/(O19) -> 2.4297738 | O19: =O18-M19 -> 2228 | U19: =((((((P19+Q19)*30)/$E$50)+((R19+S19)/$E$51))+(U18*V18))-(T19*U18))/(V19) -> 2.4535619 | V19: =V18-T19 -> 2228 | AB19: =((((((W19+X19)*30)/$E$50)+((Y19+Z19)/$E$51))+(AB18*AC18))-(AA19*AB18))/(AC19) -> 2.4535619 | AC19: =AC18-AA19 -> 2228 | AI19: =((((((AD19+AE19)*30)/$E$50)+((AF19+AG19)/$E$51))+(AI18*AJ18))-(AH19*AI18))/(AJ19) -> 2.4535619 | AJ19: =AJ18-AH19 -> 2228 | AP19: =((((((AK19+AL19)*30)/$E$50)+((AM19+AN19)/$E$51))+(AP18*AQ18))-(AO19*AP18))/(AQ19) -> 2.4535619 | AQ19: =AQ18-AO19 -> 2228 | AW19: =((((((AR19+AS19)*30)/$E$50)+((AT19+AU19)/$E$51))+(AW18*AX18))-(AV19*AW18))/(AX19) -> 2.4535619 | AX19: =AX18-AV19 -> 2228 | BD19: =((((((AY19+AZ19)*30)/$E$50)+((BA19+BB19)/$E$51))+(BD18*BE18))-(BC19*BD18))/(BE19) -> 2.4535619 | BE19: =BE18-BC19 -> 2228 | BK19: =((((((BF19+BG19)*30)/$E$50)+((BH19+BI19)/$E$51))+(BK18*BL18))-(BJ19*BK18))/(BL19) -> 2.4535619 | BL19: =BL18-BJ19 -> 2228 | BR19: =((((((BM19+BN19)*30)/$E$50)+((BO19+BP19)/$E$51))+(BR18*BS18))-(BQ19*BR18))/(BS19) -> 2.4535619 | BS19: =BS18-BQ19 -> 2228 | BY19: =((((((BT19+BU19)*30)/$E$50)+((BV19+BW19)/$E$51))+(BY18*BZ18))-(BX19*BY18))/(BZ19) -> 2.4535619 | BZ19: =BZ18-BX19 -> 2228 | CF19: =((((((CA19+CB19)*30)/$E$50)+((CC19+CD19)/$E$51))+(CF18*CG18))-(CE19*CF18))/(CG19) -> 2.4535619 | CG19: =CG18-CE19 -> 2228 | CM19: =((((((CH19+CI19)*30)/$E$50)+((CJ19+CK19)/$E$51))+(CM18*CN18))-(CL19*CM18))/(CN19) -> 2.4535619 | CN19: =CN18-CL19 -> 2228 | CT19: =((((((CO19+CP19)*30)/$E$50)+((CQ19+CR19)/$E$51))+(CT18*CU18))-(CS19*CT18))/(CU19) -> 2.4535619 | CU19: =CU18-CS19 -> 2228 | DA19: =((((((CV19+CW19)*30)/$E$50)+((CX19+CY19)/$E$51))+(DA18*DB18))-(CZ19*DA18))/(DB19) -> 2.4535619 | DB19: =DB18-CZ19 -> 2228 | DH19: =((((((DC19+DD19)*30)/$E$50)+((DE19+DF19)/$E$51))+(DH18*DI18))-(DG19*DH18))/(DI19) -> 2.4535619 | DI19: =DI18-DG19 -> 2228 | DO19: =((((((DJ19+DK19)*30)/$E$50)+((DL19+DM19)/$E$51))+(DO18*DP18))-(DN19*DO18))/(DP19) -> 2.4535619 | DP19: =DP18-DN19 -> 2228 | DV19: =((((((DQ19+DR19)*30)/$E$50)+((DS19+DT19)/$E$51))+(DV18*DW18))-(DU19*DV18))/(DW19) -> 2.4535619 | DW19: =DW18-DU19 -> 2228 | EC19: =((((((DX19+DY19)*30)/$E$50)+((DZ19+EA19)/$E$51))+(EC18*ED18))-(EB19*EC18))/(ED19) -> 2.4535619 | ED19: =ED18-EB19 -> 2228 | EJ19: =((((((EE19+EF19)*30)/$E$50)+((EG19+EH19)/$E$51))+(EJ18*EK18))-(EI19*EJ18))/(EK19) -> 2.4535619 | EK19: =EK18-EI19 -> 2228
A20: 17 | B20: 1 | E20: 10 | G20: =((((((B20+C20)*30)/$E$50)+((D20+E20)/$E$51))+(G19*H19))-(F20*G19))/(H20) -> 2.1241812 | H20: =H19-F20 -> 2235 | I20: 3 | N20: =((((((I20+J20)*30)/$E$50)+((K20+L20)/$E$51))+(N19*O19))-(M20*N19))/(O20) -> 2.4365063 | O20: =O19-M20 -> 2228 | U20: =((((((P20+Q20)*30)/$E$50)+((R20+S20)/$E$51))+(U19*V19))-(T20*U19))/(V20) -> 2.4535619 | V20: =V19-T20 -> 2228 | AB20: =((((((W20+X20)*30)/$E$50)+((Y20+Z20)/$E$51))+(AB19*AC19))-(AA20*AB19))/(AC20) -> 2.4535619 | AC20: =AC19-AA20 -> 2228 | AI20: =((((((AD20+AE20)*30)/$E$50)+((AF20+AG20)/$E$51))+(AI19*AJ19))-(AH20*AI19))/(AJ20) -> 2.4535619 | AJ20: =AJ19-AH20 -> 2228 | AP20: =((((((AK20+AL20)*30)/$E$50)+((AM20+AN20)/$E$51))+(AP19*AQ19))-(AO20*AP19))/(AQ20) -> 2.4535619 | AQ20: =AQ19-AO20 -> 2228 | AW20: =((((((AR20+AS20)*30)/$E$50)+((AT20+AU20)/$E$51))+(AW19*AX19))-(AV20*AW19))/(AX20) -> 2.4535619 | AX20: =AX19-AV20 -> 2228 | BD20: =((((((AY20+AZ20)*30)/$E$50)+((BA20+BB20)/$E$51))+(BD19*BE19))-(BC20*BD19))/(BE20) -> 2.4535619 | BE20: =BE19-BC20 -> 2228 | BK20: =((((((BF20+BG20)*30)/$E$50)+((BH20+BI20)/$E$51))+(BK19*BL19))-(BJ20*BK19))/(BL20) -> 2.4535619 | BL20: =BL19-BJ20 -> 2228 | BR20: =((((((BM20+BN20)*30)/$E$50)+((BO20+BP20)/$E$51))+(BR19*BS19))-(BQ20*BR19))/(BS20) -> 2.4535619 | BS20: =BS19-BQ20 -> 2228 | BY20: =((((((BT20+BU20)*30)/$E$50)+((BV20+BW20)/$E$51))+(BY19*BZ19))-(BX20*BY19))/(BZ20) -> 2.4535619 | BZ20: =BZ19-BX20 -> 2228 | CF20: =((((((CA20+CB20)*30)/$E$50)+((CC20+CD20)/$E$51))+(CF19*CG19))-(CE20*CF19))/(CG20) -> 2.4535619 | CG20: =CG19-CE20 -> 2228 | CM20: =((((((CH20+CI20)*30)/$E$50)+((CJ20+CK20)/$E$51))+(CM19*CN19))-(CL20*CM19))/(CN20) -> 2.4535619 | CN20: =CN19-CL20 -> 2228 | CT20: =((((((CO20+CP20)*30)/$E$50)+((CQ20+CR20)/$E$51))+(CT19*CU19))-(CS20*CT19))/(CU20) -> 2.4535619 | CU20: =CU19-CS20 -> 2228 | DA20: =((((((CV20+CW20)*30)/$E$50)+((CX20+CY20)/$E$51))+(DA19*DB19))-(CZ20*DA19))/(DB20) -> 2.4535619 | DB20: =DB19-CZ20 -> 2228 | DH20: =((((((DC20+DD20)*30)/$E$50)+((DE20+DF20)/$E$51))+(DH19*DI19))-(DG20*DH19))/(DI20) -> 2.4535619 | DI20: =DI19-DG20 -> 2228 | DO20: =((((((DJ20+DK20)*30)/$E$50)+((DL20+DM20)/$E$51))+(DO19*DP19))-(DN20*DO19))/(DP20) -> 2.4535619 | DP20: =DP19-DN20 -> 2228 | DV20: =((((((DQ20+DR20)*30)/$E$50)+((DS20+DT20)/$E$51))+(DV19*DW19))-(DU20*DV19))/(DW20) -> 2.4535619 | DW20: =DW19-DU20 -> 2228 | EC20: =((((((DX20+DY20)*30)/$E$50)+((DZ20+EA20)/$E$51))+(EC19*ED19))-(EB20*EC19))/(ED20) -> 2.4535619 | ED20: =ED19-EB20 -> 2228 | EJ20: =((((((EE20+EF20)*30)/$E$50)+((EG20+EH20)/$E$51))+(EJ19*EK19))-(EI20*EJ19))/(EK20) -> 2.4535619 | EK20: =EK19-EI20 -> 2228
A21: 18 | B21: 3 | G21: =((((((B21+C21)*30)/$E$50)+((D21+E21)/$E$51))+(G20*H20))-(F21*G20))/(H21) -> 2.1308926 | H21: =H20-F21 -> 2235 | N21: =((((((I21+J21)*30)/$E$50)+((K21+L21)/$E$51))+(N20*O20))-(M21*N20))/(O21) -> 2.4365063 | O21: =O20-M21 -> 2228 | U21: =((((((P21+Q21)*30)/$E$50)+((R21+S21)/$E$51))+(U20*V20))-(T21*U20))/(V21) -> 2.4535619 | V21: =V20-T21 -> 2228 | AB21: =((((((W21+X21)*30)/$E$50)+((Y21+Z21)/$E$51))+(AB20*AC20))-(AA21*AB20))/(AC21) -> 2.4535619 | AC21: =AC20-AA21 -> 2228 | AI21: =((((((AD21+AE21)*30)/$E$50)+((AF21+AG21)/$E$51))+(AI20*AJ20))-(AH21*AI20))/(AJ21) -> 2.4535619 | AJ21: =AJ20-AH21 -> 2228 | AP21: =((((((AK21+AL21)*30)/$E$50)+((AM21+AN21)/$E$51))+(AP20*AQ20))-(AO21*AP20))/(AQ21) -> 2.4535619 | AQ21: =AQ20-AO21 -> 2228 | AW21: =((((((AR21+AS21)*30)/$E$50)+((AT21+AU21)/$E$51))+(AW20*AX20))-(AV21*AW20))/(AX21) -> 2.4535619 | AX21: =AX20-AV21 -> 2228 | BD21: =((((((AY21+AZ21)*30)/$E$50)+((BA21+BB21)/$E$51))+(BD20*BE20))-(BC21*BD20))/(BE21) -> 2.4535619 | BE21: =BE20-BC21 -> 2228 | BK21: =((((((BF21+BG21)*30)/$E$50)+((BH21+BI21)/$E$51))+(BK20*BL20))-(BJ21*BK20))/(BL21) -> 2.4535619 | BL21: =BL20-BJ21 -> 2228 | BR21: =((((((BM21+BN21)*30)/$E$50)+((BO21+BP21)/$E$51))+(BR20*BS20))-(BQ21*BR20))/(BS21) -> 2.4535619 | BS21: =BS20-BQ21 -> 2228 | BY21: =((((((BT21+BU21)*30)/$E$50)+((BV21+BW21)/$E$51))+(BY20*BZ20))-(BX21*BY20))/(BZ21) -> 2.4535619 | BZ21: =BZ20-BX21 -> 2228 | CF21: =((((((CA21+CB21)*30)/$E$50)+((CC21+CD21)/$E$51))+(CF20*CG20))-(CE21*CF20))/(CG21) -> 2.4535619 | CG21: =CG20-CE21 -> 2228 | CM21: =((((((CH21+CI21)*30)/$E$50)+((CJ21+CK21)/$E$51))+(CM20*CN20))-(CL21*CM20))/(CN21) -> 2.4535619 | CN21: =CN20-CL21 -> 2228 | CT21: =((((((CO21+CP21)*30)/$E$50)+((CQ21+CR21)/$E$51))+(CT20*CU20))-(CS21*CT20))/(CU21) -> 2.4535619 | CU21: =CU20-CS21 -> 2228 | DA21: =((((((CV21+CW21)*30)/$E$50)+((CX21+CY21)/$E$51))+(DA20*DB20))-(CZ21*DA20))/(DB21) -> 2.4535619 | DB21: =DB20-CZ21 -> 2228 | DH21: =((((((DC21+DD21)*30)/$E$50)+((DE21+DF21)/$E$51))+(DH20*DI20))-(DG21*DH20))/(DI21) -> 2.4535619 | DI21: =DI20-DG21 -> 2228 | DO21: =((((((DJ21+DK21)*30)/$E$50)+((DL21+DM21)/$E$51))+(DO20*DP20))-(DN21*DO20))/(DP21) -> 2.4535619 | DP21: =DP20-DN21 -> 2228 | DV21: =((((((DQ21+DR21)*30)/$E$50)+((DS21+DT21)/$E$51))+(DV20*DW20))-(DU21*DV20))/(DW21) -> 2.4535619 | DW21: =DW20-DU21 -> 2228 | EC21: =((((((DX21+DY21)*30)/$E$50)+((DZ21+EA21)/$E$51))+(EC20*ED20))-(EB21*EC20))/(ED21) -> 2.4535619 | ED21: =ED20-EB21 -> 2228 | EJ21: =((((((EE21+EF21)*30)/$E$50)+((EG21+EH21)/$E$51))+(EJ20*EK20))-(EI21*EJ20))/(EK21) -> 2.4535619 | EK21: =EK20-EI21 -> 2228
